Workbook

Sheet Criterios
A1: PUNTO 4 — RELACIÓN TEMPERATURA–ELEVACIÓN
A2: Cuenca del río Cauca hasta la presa de Hidroituango. Fuente: IDEAM, Promedios Climatológicos 1981–2010.
A3: Modelo: T = T0 − α·Z (regresión T = a + b·Z ⇒ T0 = a, α = −b; Anexo 1)
A5: Criterios de selección de estaciones
A6: 1. Ubicación dentro de la cuenca delimitada (DEM GLO-30, 90 m).
A7: 2. Tmed, Tmax y Tmin con los 12 meses completos; el mismo conjunto de estaciones para las tres regresiones.
A8: 3. Coherencia física: Tmin < Tmed < Tmax.
A9: 4. Ubicación verificable: se excluye Aragón (27015110); su coordenada cae a 512 m en el cañón del Cauca, pero la estación está a 2600 m en Santa Rosa de Osos (cuenca del Nechí).
A10: 5. Atípicos: |residuo estudentizado| > 2.5. Se señalan y se conservan; ver hoja 'Sensibilidad_atipicos'.
A11: Z = elevación del catálogo IDEAM (medida en la estación). La hoja 'Inventario' compara con el DEM.
A13: Estaciones en la cuenca: 54 | Seleccionadas: 47 | Rango de Z: 530–4150 m
A15: Hojas: Inventario · Datos_anuales (cálculos por estación) · Regresiones (resultados) · Datos_mensuales · Regresiones_mensuales (insumo ETP Hargreaves) · Sensibilidad_atipicos · Diagramas
A16: Todas las celdas de cálculo son fórmulas de Excel (INTERSECCION.EJE, PENDIENTE, COEFICIENTE.R2, ERROR.TIPICO.XY…).

Sheet Inventario
A1: Código | B1: Nombre | C1: Municipio | D1: Departamento | E1: Cat. | F1: Z catálogo (m) | G1: Z DEM (m) | H1: Z cat − Z DEM (m) | I1: Meses Tmed | J1: Meses Tmax | K1: Meses Tmin | L1: Tmed (°C) | M1: Tmax (°C) | N1: Tmin (°C) | O1: Seleccionada | P1: Motivo de exclusión
A2: 26235030 | B2: Matanzas | C2: Toledo | D2: Antioquia | E2: CO | F2: 500 | G2: 523 | H2: -23 | I2: 0 | J2: 12 | K2: 0 | M2: 31.951136 | O2: No | P2: Serie incompleta (< 12 meses) en Tmin, Tmed
A3: 26175040 | B3: Tunez Hda | C3: Fredonia | D3: Antioquia | E3: CO | F3: 530 | G3: 583 | H3: -53 | I3: 12 | J3: 12 | K3: 12 | L3: 25.966461 | M3: 32.860499 | N3: 19.525878 | O3: Sí
A4: 26225030 | B4: Cotove Hda | C4: Santafe de Antioquia | D4: Antioquia | E4: AM | F4: 530 | G4: 512 | H4: 18 | I4: 12 | J4: 12 | K4: 12 | L4: 27.038194 | M4: 34.537764 | N4: 20.446597 | O4: Sí
A5: 26115040 | B5: Cent Admo La Union | C5: La Union | D5: Valle del Cauca | E5: CP | F5: 920 | G5: 908 | H5: 12 | I5: 12 | J5: 12 | K5: 12 | L5: 24.304167 | M5: 30.628819 | N5: 18.773056 | O5: Sí
A6: 26105110 | B6: Ing Riopaila | C6: Zarzal | D6: Valle del Cauca | E6: CO | F6: 941 | G6: 929 | H6: 12 | I6: 12 | J6: 12 | K6: 12 | L6: 24.317269 | M6: 31.081465 | N6: 18.326052 | O6: Sí
A7: 26085120 | B7: Base Aerea MFS | C7: Cali | D7: Valle del Cauca | E7: SS | F7: 954 | G7: 960 | H7: -6 | I7: 12 | J7: 12 | K7: 12 | L7: 25.194366 | M7: 29.955524 | N7: 19.652945 | O7: Sí
A8: 26105160 | B8: Apto Farfan | C8: Tulua | D8: Valle del Cauca | E8: SP | F8: 955 | G8: 957 | H8: -2 | I8: 12 | J8: 12 | K8: 12 | L8: 23.891028 | M8: 29.919259 | N8: 18.471147 | O8: Sí
A9: 26075040 | B9: Apto A Bonilla | C9: Palmira | D9: Valle del Cauca | E9: SP | F9: 961 | G9: 962 | H9: -1 | I9: 12 | J9: 12 | K9: 12 | L9: 23.924722 | M9: 29.739444 | N9: 18.883611 | O9: Sí
A10: 26135100 | B10: Bohemia La | C10: Pereira | D10: Risaralda | E10: CO | F10: 970 | G10: 970 | H10: 0 | I10: 12 | J10: 12 | K10: 12 | L10: 23.922475 | M10: 30.083576 | N10: 19.094167 | O10: Sí
A11: 26095230 | B11: Vinculo El | C11: Guadalajara de Buga | D11: Valle del Cauca | E11: AM | F11: 979 | G11: 983 | H11: -4 | I11: 12 | J11: 12 | K11: 12 | L11: 23.591134 | M11: 29.864013 | N11: 18.803819 | O11: Sí
A12: 26055070 | B12: Univ del Valle | C12: Cali | D12: Valle del Cauca | E12: CP | F12: 985 | G12: 976 | H12: 9 | I12: 12 | J12: 12 | K12: 12 | L12: 24.475884 | M12: 29.885556 | N12: 19.236111 | O12: Sí
A13: 26065010 | B13: Ing Cauca | C13: Miranda | D13: Cauca | E13: CO | F13: 1000 | G13: 986 | H13: 14 | I13: 12 | J13: 12 | K13: 12 | L13: 23.469654 | M13: 29.772073 | N13: 18.553289 | O13: Sí
A14: 26045010 | B14: Ing Bengala | C14: Puerto Tejada | D14: Cauca | E14: CO | F14: 1000 | G14: 965 | H14: 35 | I14: 12 | J14: 12 | K14: 12 | L14: 24.034226 | M14: 29.891831 | N14: 17.924388 | O14: Sí
... A17: 26025030 | B17: Japio | C17: Santander de Quilichao | D17: Cauca | E17: CO | F17: 1015 | G17: 1009 | H17: 6 | I17: 12 | J17: 12 | K17: 12 | L17: 23.550794 | M17: 29.029012 | N17: 18.349583 | O17: Sí
A18: 26145050 | B18: Samaria La | C18: Viterbo | D18: Caldas | E18: CO | F18: 1020 | G18: 978 | H18: 42 | I18: 12 | J18: 12 | K18: 0 | L18: 24.481778 | M18: 29.662121 | O18: No | P18: Serie incompleta (< 12 meses) en Tmin
A19: 26105230 | B19: Mateguadua | C19: Tulua | D19: Valle del Cauca | E19: CO | F19: 1025 | G19: 1111 | H19: -86 | I19: 12 | J19: 12 | K19: 12 | L19: 22.597685 | M19: 29.497115 | N19: 17.432099 | O19: Sí
A20: 26075010 | B20: Palmira Ica | C20: Palmira | D20: Valle del Cauca | E20: AM | F20: 1050 | G20: 988 | H20: 62 | I20: 12 | J20: 12 | K20: 12 | L20: 23.611983 | M20: 29.418182 | N20: 19.137879 | O20: Sí
A21: 26075050 | B21: Ing Manuelita Porv | C21: Palmira | D21: Valle del Cauca | E21: CO | F21: 1058 | G21: 1033 | H21: 25 | I21: 12 | J21: 0 | K21: 12 | L21: 23.051481 | N21: 18.841751 | O21: No | P21: Serie incompleta (< 12 meses) en Tmax
A22: 26065020 | B22: Miranda | C22: Miranda | D22: Cauca | E22: CO | F22: 1128 | G22: 1103 | H22: 25 | I22: 12 | J22: 12 | K22: 12 | L22: 23.481591 | M22: 29.176228 | N22: 18.138333 | O22: Sí
A23: 26175030 | B23: Nacional Gja La | C23: Tamesis | D23: Antioquia | E23: CP | F23: 1151 | G23: 1141 | H23: 10 | I23: 12 | J23: 12 | K23: 12 | L23: 22.613793 | M23: 27.601407 | N23: 18.49083 | O23: Sí
A24: 26195020 | B24: Ita Andes | C24: Andes | D24: Antioquia | E24: CO | F24: 1180 | G24: 1212 | H24: -32 | I24: 12 | J24: 12 | K24: 12 | L24: 21.994761 | M24: 28.67755 | N24: 16.719923 | O24: Sí
A25: 26125060 | B25: Apto El Eden | C25: Armenia | D25: Quindio | E25: SP | F25: 1229 | G25: 1214 | H25: 15 | I25: 12 | J25: 12 | K25: 12 | L25: 22.067778 | M25: 27.581111 | N25: 16.746111 | O25: Sí
A26: 26095180 | B26: San Emigdio | C26: Palmira | D26: Valle del Cauca | E26: CO | F26: 1272 | G26: 1287 | H26: -15 | I26: 0 | J26: 12 | K26: 12 | M26: 23.224808 | N26: 15.547863 | O26: No | P26: Serie incompleta (< 12 meses) en Tmed
A27: 26175070 | B27: Rafael Escobar | C27: Supia | D27: Caldas | E27: CO | F27: 1320 | G27: 1282 | H27: 38 | I27: 12 | J27: 12 | K27: 12 | L27: 22.067308 | M27: 27.695513 | N27: 17.391667 | O27: Sí
A28: 26135040 | B28: Apto Matecana | C28: Pereira | D28: Risaralda | E28: SP | F28: 1342 | G28: 1348 | H28: -6 | I28: 12 | J28: 12 | K28: 12 | L28: 21.540833 | M28: 26.336389 | N28: 17.363056 | O28: Sí
A29: 26125070 | B29: Bella La | C29: Calarca | D29: Quindio | E29: CO | F29: 1450 | G29: 1470 | H29: -20 | I29: 12 | J29: 12 | K29: 12 | L29: 20.60202 | M29: 25.43548 | N29: 16.237058 | O29: Sí
A30: 26085130 | B30: Buitrera La | C30: Yumbo | D30: Valle del Cauca | E30: CO | F30: 1500 | G30: 2093 | H30: -593 | I30: 12 | J30: 12 | K30: 12 | L30: 20.699232 | M30: 26.176607 | N30: 16.415938 | O30: Sí
A31: 26195010 | B31: Miguel Valencia | C31: Jardin | D31: Antioquia | E31: CO | F31: 1570 | G31: 2314 | H31: -744 | I31: 12 | J31: 12 | K31: 12 | L31: 19.235256 | M31: 25.389744 | N31: 15.055769 | O31: Sí
A32: 26205020 | B32: Rosario El | C32: Venecia | D32: Antioquia | E32: CP | F32: 1600 | G32: 2136 | H32: -536 | I32: 12 | J32: 12 | K32: 12 | L32: 20.224359 | M32: 24.838462 | N32: 16.037821 | O32: Sí
A33: 26135060 | B33: Jazmin El | C33: Santa Rosa de Cabal | D33: Risaralda | E33: CO | F33: 1600 | G33: 1626 | H33: -26 | I33: 12 | J33: 12 | K33: 12 | L33: 19.565741 | M33: 24.732639 | N33: 15.397685 | O33: Sí
A34: 26225040 | B34: Piunti Hda | C34: Buritica | D34: Antioquia | E34: CO | F34: 1650 | G34: 1594 | H34: 56 | I34: 12 | J34: 12 | K34: 0 | L34: 20.729045 | M34: 25.805409 | O34: No | P34: Serie incompleta (< 12 meses) en Tmin
A35: 26145030 | B35: Camelia La | C35: Santuario | D35: Risaralda | E35: CO | F35: 1650 | G35: 1723 | H35: -73 | I35: 12 | J35: 12 | K35: 12 | L35: 19.191389 | M35: 23.608889 | N35: 16.171351 | O35: Sí
A36: 26125130 | B36: Cumbarco | C36: Sevilla | D36: Valle del Cauca | E36: CO | F36: 1692 | G36: 1722 | H36: -30 | I36: 12 | J36: 12 | K36: 12 | L36: 18.875 | M36: 23.353835 | N36: 15.106944 | O36: Sí
A37: 26135110 | B37: Veracruz | C37: Pereira | D37: Risaralda | E37: CO | F37: 1720 | G37: 1683 | H37: 37 | I37: 12 | J37: 12 | K37: 12 | L37: 18.766667 | M37: 23.776389 | N37: 14.572989 | O37: Sí
A38: 26035030 | B38: Apto G L Valencia | C38: Popayan | D38: Cauca | E38: SP | F38: 1749 | G38: 1727 | H38: 22 | I38: 0 | J38: 12 | K38: 12 | M38: 24.873056 | N38: 13.410202 | O38: No | P38: Serie incompleta (< 12 meses) en Tmed
A39: 26025100 | B39: Tunia | C39: Piendamo | D39: Cauca | E39: CO | F39: 1800 | G39: 1797 | H39: 3 | I39: 12 | J39: 12 | K39: 12 | L39: 19.065227 | M39: 23.795238 | N39: 14.380952 | O39: Sí
A40: 26025090 | B40: Venta De Cajibio | C40: Cajibio | D40: Cauca | E40: CO | F40: 1850 | G40: 1829 | H40: 21 | I40: 12 | J40: 12 | K40: 12 | L40: 18.494444 | M40: 24.521239 | N40: 13.726818 | O40: Sí
A41: 26215010 | B41: Concordia | C41: Concordia | D41: Antioquia | E41: CO | F41: 1904 | G41: 1972 | H41: -68 | I41: 12 | J41: 12 | K41: 12 | L41: 18.510977 | M41: 23.230801 | N41: 14.270947 | O41: Sí
A42: 26145020 | B42: Bellavista | C42: Anserma | D42: Caldas | E42: CO | F42: 1932 | G42: 1990 | H42: -58 | I42: 12 | J42: 12 | K42: 12 | L42: 17.009298 | M42: 21.509414 | N42: 13.382554 | O42: Sí
...

Sheet Datos_anuales
A1: Código | B1: Nombre | C1: Municipio | D1: Z (m) | E1: Tmax (°C) | F1: Tmin (°C) | G1: Tmed (°C) | H1: (Tmax+Tmin)/2 (°C) | I1: Tmax · T estimada | J1: Tmax · Residuo | K1: Tmax · Leverage h | L1: Tmax · Residuo estudentizado | M1: Tmax · ¿Atípico? | N1: Tmin · T estimada | O1: Tmin · Residuo | P1: Tmin · Leverage h | Q1: Tmin · Residuo estudentizado | R1: Tmin · ¿Atípico? | S1: Tmed · T estimada | T1: Tmed · Residuo | U1: Tmed · Leverage h | V1: Tmed · Residuo estudentizado | W1: Tmed · ¿Atípico?
A2: 26175040 | B2: Tunez Hda | C2: Fredonia | D2: 530 | E2: 32.860499 | F2: 19.525878 | G2: 25.966461 | H2: =(E2+F2)/2 | I2: =Regresiones!$C$2+Regresiones!$D$2*D2 | J2: =E2-I2 | K2: =1/COUNT($D$2:$D$48)+(D2-AVERAGE($D$2:$D$48))^2/DEVSQ($D$2:$D$48) | L2: =J2/(Regresiones!$J$2*SQRT(1-K2)) | M2: =IF(ABS(L2)>2.5,"Sí","No") | N2: =Regresiones!$C$3+Regresiones!$D$3*D2 | O2: =F2-N2 | P2: =1/COUNT($D$2:$D$48)+(D2-AVERAGE($D$2:$D$48))^2/DEVSQ($D$2:$D$48) | Q2: =O2/(Regresiones!$J$3*SQRT(1-P2)) | R2: =IF(ABS(Q2)>2.5,"Sí","No") | S2: =Regresiones!$C$4+Regresiones!$D$4*D2 | T2: =G2-S2 | U2: =1/COUNT($D$2:$D$48)+(D2-AVERAGE($D$2:$D$48))^2/DEVSQ($D$2:$D$48) | V2: =T2/(Regresiones!$J$4*SQRT(1-U2)) | W2: =IF(ABS(V2)>2.5,"Sí","No")
A3: 26225030 | B3: Cotove Hda | C3: Santafe de Antioquia | D3: 530 | E3: 34.537764 | F3: 20.446597 | G3: 27.038194 | H3: =(E3+F3)/2 | I3: =Regresiones!$C$2+Regresiones!$D$2*D3 | J3: =E3-I3 | K3: =1/COUNT($D$2:$D$48)+(D3-AVERAGE($D$2:$D$48))^2/DEVSQ($D$2:$D$48) | L3: =J3/(Regresiones!$J$2*SQRT(1-K3)) | M3: =IF(ABS(L3)>2.5,"Sí","No") | N3: =Regresiones!$C$3+Regresiones!$D$3*D3 | O3: =F3-N3 | P3: =1/COUNT($D$2:$D$48)+(D3-AVERAGE($D$2:$D$48))^2/DEVSQ($D$2:$D$48) | Q3: =O3/(Regresiones!$J$3*SQRT(1-P3)) | R3: =IF(ABS(Q3)>2.5,"Sí","No") | S3: =Regresiones!$C$4+Regresiones!$D$4*D3 | T3: =G3-S3 | U3: =1/COUNT($D$2:$D$48)+(D3-AVERAGE($D$2:$D$48))^2/DEVSQ($D$2:$D$48) | V3: =T3/(Regresiones!$J$4*SQRT(1-U3)) | W3: =IF(ABS(V3)>2.5,"Sí","No")
A4: 26115040 | B4: Cent Admo La Union | C4: La Union | D4: 920 | E4: 30.628819 | F4: 18.773056 | G4: 24.304167 | H4: =(E4+F4)/2 | I4: =Regresiones!$C$2+Regresiones!$D$2*D4 | J4: =E4-I4 | K4: =1/COUNT($D$2:$D$48)+(D4-AVERAGE($D$2:$D$48))^2/DEVSQ($D$2:$D$48) | L4: =J4/(Regresiones!$J$2*SQRT(1-K4)) | M4: =IF(ABS(L4)>2.5,"Sí","No") | N4: =Regresiones!$C$3+Regresiones!$D$3*D4 | O4: =F4-N4 | P4: =1/COUNT($D$2:$D$48)+(D4-AVERAGE($D$2:$D$48))^2/DEVSQ($D$2:$D$48) | Q4: =O4/(Regresiones!$J$3*SQRT(1-P4)) | R4: =IF(ABS(Q4)>2.5,"Sí","No") | S4: =Regresiones!$C$4+Regresiones!$D$4*D4 | T4: =G4-S4 | U4: =1/COUNT($D$2:$D$48)+(D4-AVERAGE($D$2:$D$48))^2/DEVSQ($D$2:$D$48) | V4: =T4/(Regresiones!$J$4*SQRT(1-U4)) | W4: =IF(ABS(V4)>2.5,"Sí","No")
A5: 26105110 | B5: Ing Riopaila | C5: Zarzal | D5: 941 | E5: 31.081465 | F5: 18.326052 | G5: 24.317269 | H5: =(E5+F5)/2 | I5: =Regresiones!$C$2+Regresiones!$D$2*D5 | J5: =E5-I5 | K5: =1/COUNT($D$2:$D$48)+(D5-AVERAGE($D$2:$D$48))^2/DEVSQ($D$2:$D$48) | L5: =J5/(Regresiones!$J$2*SQRT(1-K5)) | M5: =IF(ABS(L5)>2.5,"Sí","No") | N5: =Regresiones!$C$3+Regresiones!$D$3*D5 | O5: =F5-N5 | P5: =1/COUNT($D$2:$D$48)+(D5-AVERAGE($D$2:$D$48))^2/DEVSQ($D$2:$D$48) | Q5: =O5/(Regresiones!$J$3*SQRT(1-P5)) | R5: =IF(ABS(Q5)>2.5,"Sí","No") | S5: =Regresiones!$C$4+Regresiones!$D$4*D5 | T5: =G5-S5 | U5: =1/COUNT($D$2:$D$48)+(D5-AVERAGE($D$2:$D$48))^2/DEVSQ($D$2:$D$48) | V5: =T5/(Regresiones!$J$4*SQRT(1-U5)) | W5: =IF(ABS(V5)>2.5,"Sí","No")
A6: 26085120 | B6: Base Aerea MFS | C6: Cali | D6: 954 | E6: 29.955524 | F6: 19.652945 | G6: 25.194366 | H6: =(E6+F6)/2 | I6: =Regresiones!$C$2+Regresiones!$D$2*D6 | J6: =E6-I6 | K6: =1/COUNT($D$2:$D$48)+(D6-AVERAGE($D$2:$D$48))^2/DEVSQ($D$2:$D$48) | L6: =J6/(Regresiones!$J$2*SQRT(1-K6)) | M6: =IF(ABS(L6)>2.5,"Sí","No") | N6: =Regresiones!$C$3+Regresiones!$D$3*D6 | O6: =F6-N6 | P6: =1/COUNT($D$2:$D$48)+(D6-AVERAGE($D$2:$D$48))^2/DEVSQ($D$2:$D$48) | Q6: =O6/(Regresiones!$J$3*SQRT(1-P6)) | R6: =IF(ABS(Q6)>2.5,"Sí","No") | S6: =Regresiones!$C$4+Regresiones!$D$4*D6 | T6: =G6-S6 | U6: =1/COUNT($D$2:$D$48)+(D6-AVERAGE($D$2:$D$48))^2/DEVSQ($D$2:$D$48) | V6: =T6/(Regresiones!$J$4*SQRT(1-U6)) | W6: =IF(ABS(V6)>2.5,"Sí","No")
A7: 26105160 | B7: Apto Farfan | C7: Tulua | D7: 955 | E7: 29.919259 | F7: 18.471147 | G7: 23.891028 | H7: =(E7+F7)/2 | I7: =Regresiones!$C$2+Regresiones!$D$2*D7 | J7: =E7-I7 | K7: =1/COUNT($D$2:$D$48)+(D7-AVERAGE($D$2:$D$48))^2/DEVSQ($D$2:$D$48) | L7: =J7/(Regresiones!$J$2*SQRT(1-K7)) | M7: =IF(ABS(L7)>2.5,"Sí","No") | N7: =Regresiones!$C$3+Regresiones!$D$3*D7 | O7: =F7-N7 | P7: =1/COUNT($D$2:$D$48)+(D7-AVERAGE($D$2:$D$48))^2/DEVSQ($D$2:$D$48) | Q7: =O7/(Regresiones!$J$3*SQRT(1-P7)) | R7: =IF(ABS(Q7)>2.5,"Sí","No") | S7: =Regresiones!$C$4+Regresiones!$D$4*D7 | T7: =G7-S7 | U7: =1/COUNT($D$2:$D$48)+(D7-AVERAGE($D$2:$D$48))^2/DEVSQ($D$2:$D$48) | V7: =T7/(Regresiones!$J$4*SQRT(1-U7)) | W7: =IF(ABS(V7)>2.5,"Sí","No")
A8: 26075040 | B8: Apto A Bonilla | C8: Palmira | D8: 961 | E8: 29.739444 | F8: 18.883611 | G8: 23.924722 | H8: =(E8+F8)/2 | I8: =Regresiones!$C$2+Regresiones!$D$2*D8 | J8: =E8-I8 | K8: =1/COUNT($D$2:$D$48)+(D8-AVERAGE($D$2:$D$48))^2/DEVSQ($D$2:$D$48) | L8: =J8/(Regresiones!$J$2*SQRT(1-K8)) | M8: =IF(ABS(L8)>2.5,"Sí","No") | N8: =Regresiones!$C$3+Regresiones!$D$3*D8 | O8: =F8-N8 | P8: =1/COUNT($D$2:$D$48)+(D8-AVERAGE($D$2:$D$48))^2/DEVSQ($D$2:$D$48) | Q8: =O8/(Regresiones!$J$3*SQRT(1-P8)) | R8: =IF(ABS(Q8)>2.5,"Sí","No") | S8: =Regresiones!$C$4+Regresiones!$D$4*D8 | T8: =G8-S8 | U8: =1/COUNT($D$2:$D$48)+(D8-AVERAGE($D$2:$D$48))^2/DEVSQ($D$2:$D$48) | V8: =T8/(Regresiones!$J$4*SQRT(1-U8)) | W8: =IF(ABS(V8)>2.5,"Sí","No")
A9: 26135100 | B9: Bohemia La | C9: Pereira | D9: 970 | E9: 30.083576 | F9: 19.094167 | G9: 23.922475 | H9: =(E9+F9)/2 | I9: =Regresiones!$C$2+Regresiones!$D$2*D9 | J9: =E9-I9 | K9: =1/COUNT($D$2:$D$48)+(D9-AVERAGE($D$2:$D$48))^2/DEVSQ($D$2:$D$48) | L9: =J9/(Regresiones!$J$2*SQRT(1-K9)) | M9: =IF(ABS(L9)>2.5,"Sí","No") | N9: =Regresiones!$C$3+Regresiones!$D$3*D9 | O9: =F9-N9 | P9: =1/COUNT($D$2:$D$48)+(D9-AVERAGE($D$2:$D$48))^2/DEVSQ($D$2:$D$48) | Q9: =O9/(Regresiones!$J$3*SQRT(1-P9)) | R9: =IF(ABS(Q9)>2.5,"Sí","No") | S9: =Regresiones!$C$4+Regresiones!$D$4*D9 | T9: =G9-S9 | U9: =1/COUNT($D$2:$D$48)+(D9-AVERAGE($D$2:$D$48))^2/DEVSQ($D$2:$D$48) | V9: =T9/(Regresiones!$J$4*SQRT(1-U9)) | W9: =IF(ABS(V9)>2.5,"Sí","No")
A10: 26095230 | B10: Vinculo El | C10: Guadalajara de Buga | D10: 979 | E10: 29.864013 | F10: 18.803819 | G10: 23.591134 | H10: =(E10+F10)/2 | I10: =Regresiones!$C$2+Regresiones!$D$2*D10 | J10: =E10-I10 | K10: =1/COUNT($D$2:$D$48)+(D10-AVERAGE($D$2:$D$48))^2/DEVSQ($D$2:$D$48) | L10: =J10/(Regresiones!$J$2*SQRT(1-K10)) | M10: =IF(ABS(L10)>2.5,"Sí","No") | N10: =Regresiones!$C$3+Regresiones!$D$3*D10 | O10: =F10-N10 | P10: =1/COUNT($D$2:$D$48)+(D10-AVERAGE($D$2:$D$48))^2/DEVSQ($D$2:$D$48) | Q10: =O10/(Regresiones!$J$3*SQRT(1-P10)) | R10: =IF(ABS(Q10)>2.5,"Sí","No") | S10: =Regresiones!$C$4+Regresiones!$D$4*D10 | T10: =G10-S10 | U10: =1/COUNT($D$2:$D$48)+(D10-AVERAGE($D$2:$D$48))^2/DEVSQ($D$2:$D$48) | V10: =T10/(Regresiones!$J$4*SQRT(1-U10)) | W10: =IF(ABS(V10)>2.5,"Sí","No")
A11: 26055070 | B11: Univ del Valle | C11: Cali | D11: 985 | E11: 29.885556 | F11: 19.236111 | G11: 24.475884 | H11: =(E11+F11)/2 | I11: =Regresiones!$C$2+Regresiones!$D$2*D11 | J11: =E11-I11 | K11: =1/COUNT($D$2:$D$48)+(D11-AVERAGE($D$2:$D$48))^2/DEVSQ($D$2:$D$48) | L11: =J11/(Regresiones!$J$2*SQRT(1-K11)) | M11: =IF(ABS(L11)>2.5,"Sí","No") | N11: =Regresiones!$C$3+Regresiones!$D$3*D11 | O11: =F11-N11 | P11: =1/COUNT($D$2:$D$48)+(D11-AVERAGE($D$2:$D$48))^2/DEVSQ($D$2:$D$48) | Q11: =O11/(Regresiones!$J$3*SQRT(1-P11)) | R11: =IF(ABS(Q11)>2.5,"Sí","No") | S11: =Regresiones!$C$4+Regresiones!$D$4*D11 | T11: =G11-S11 | U11: =1/COUNT($D$2:$D$48)+(D11-AVERAGE($D$2:$D$48))^2/DEVSQ($D$2:$D$48) | V11: =T11/(Regresiones!$J$4*SQRT(1-U11)) | W11: =IF(ABS(V11)>2.5,"Sí","No")
A12: 26065010 | B12: Ing Cauca | C12: Miranda | D12: 1000 | E12: 29.772073 | F12: 18.553289 | G12: 23.469654 | H12: =(E12+F12)/2 | I12: =Regresiones!$C$2+Regresiones!$D$2*D12 | J12: =E12-I12 | K12: =1/COUNT($D$2:$D$48)+(D12-AVERAGE($D$2:$D$48))^2/DEVSQ($D$2:$D$48) | L12: =J12/(Regresiones!$J$2*SQRT(1-K12)) | M12: =IF(ABS(L12)>2.5,"Sí","No") | N12: =Regresiones!$C$3+Regresiones!$D$3*D12 | O12: =F12-N12 | P12: =1/COUNT($D$2:$D$48)+(D12-AVERAGE($D$2:$D$48))^2/DEVSQ($D$2:$D$48) | Q12: =O12/(Regresiones!$J$3*SQRT(1-P12)) | R12: =IF(ABS(Q12)>2.5,"Sí","No") | S12: =Regresiones!$C$4+Regresiones!$D$4*D12 | T12: =G12-S12 | U12: =1/COUNT($D$2:$D$48)+(D12-AVERAGE($D$2:$D$48))^2/DEVSQ($D$2:$D$48) | V12: =T12/(Regresiones!$J$4*SQRT(1-U12)) | W12: =IF(ABS(V12)>2.5,"Sí","No")
A13: 26045010 | B13: Ing Bengala | C13: Puerto Tejada | D13: 1000 | E13: 29.891831 | F13: 17.924388 | G13: 24.034226 | H13: =(E13+F13)/2 | I13: =Regresiones!$C$2+Regresiones!$D$2*D13 | J13: =E13-I13 | K13: =1/COUNT($D$2:$D$48)+(D13-AVERAGE($D$2:$D$48))^2/DEVSQ($D$2:$D$48) | L13: =J13/(Regresiones!$J$2*SQRT(1-K13)) | M13: =IF(ABS(L13)>2.5,"Sí","No") | N13: =Regresiones!$C$3+Regresiones!$D$3*D13 | O13: =F13-N13 | P13: =1/COUNT($D$2:$D$48)+(D13-AVERAGE($D$2:$D$48))^2/DEVSQ($D$2:$D$48) | Q13: =O13/(Regresiones!$J$3*SQRT(1-P13)) | R13: =IF(ABS(Q13)>2.5,"Sí","No") | S13: =Regresiones!$C$4+Regresiones!$D$4*D13 | T13: =G13-S13 | U13: =1/COUNT($D$2:$D$48)+(D13-AVERAGE($D$2:$D$48))^2/DEVSQ($D$2:$D$48) | V13: =T13/(Regresiones!$J$4*SQRT(1-U13)) | W13: =IF(ABS(V13)>2.5,"Sí","No")
... A48: 26155150 | B48: Brisas Las | C48: Villamaria | D48: 4150 | E48: 8.4322222 | F48: 1.2326149 | G48: 4.6362644 | H48: =(E48+F48)/2 | I48: =Regresiones!$C$2+Regresiones!$D$2*D48 | J48: =E48-I48 | K48: =1/COUNT($D$2:$D$48)+(D48-AVERAGE($D$2:$D$48))^2/DEVSQ($D$2:$D$48) | L48: =J48/(Regresiones!$J$2*SQRT(1-K48)) | M48: =IF(ABS(L48)>2.5,"Sí","No") | N48: =Regresiones!$C$3+Regresiones!$D$3*D48 | O48: =F48-N48 | P48: =1/COUNT($D$2:$D$48)+(D48-AVERAGE($D$2:$D$48))^2/DEVSQ($D$2:$D$48) | Q48: =O48/(Regresiones!$J$3*SQRT(1-P48)) | R48: =IF(ABS(Q48)>2.5,"Sí","No") | S48: =Regresiones!$C$4+Regresiones!$D$4*D48 | T48: =G48-S48 | U48: =1/COUNT($D$2:$D$48)+(D48-AVERAGE($D$2:$D$48))^2/DEVSQ($D$2:$D$48) | V48: =T48/(Regresiones!$J$4*SQRT(1-U48)) | W48: =IF(ABS(V48)>2.5,"Sí","No")

Sheet Regresiones
A1: Variable | B1: n | C1: a = T0 (°C) | D1: b (°C/m) | E1: α = −b (°C/m) | F1: α (°C/km) | G1: R² (COEFICIENTE.R2) | H1: R² Anexo 1 = 1 − Σe²/Σ(T−T̄)² | I1: r (Pearson) | J1: Error típico s (°C) | K1: Ecuación
A2: Tmax | B2: =COUNT(Datos_anuales!$E$2:$E$48) | C2: =INTERCEPT(Datos_anuales!$E$2:$E$48,Datos_anuales!$D$2:$D$48) | D2: =SLOPE(Datos_anuales!$E$2:$E$48,Datos_anuales!$D$2:$D$48) | E2: =-D2 | F2: =1000*E2 | G2: =RSQ(Datos_anuales!$E$2:$E$48,Datos_anuales!$D$2:$D$48) | H2: =1-SUMSQ(Datos_anuales!$J$2:$J$48)/DEVSQ(Datos_anuales!$E$2:$E$48) | I2: =CORREL(Datos_anuales!$E$2:$E$48,Datos_anuales!$D$2:$D$48) | J2: =STEYX(Datos_anuales!$E$2:$E$48,Datos_anuales!$D$2:$D$48) | K2: ="Tmax = "&TEXT(C2,"0.00")&" − "&TEXT(E2,"0.00000")&"·Z"
A3: Tmin | B3: =COUNT(Datos_anuales!$F$2:$F$48) | C3: =INTERCEPT(Datos_anuales!$F$2:$F$48,Datos_anuales!$D$2:$D$48) | D3: =SLOPE(Datos_anuales!$F$2:$F$48,Datos_anuales!$D$2:$D$48) | E3: =-D3 | F3: =1000*E3 | G3: =RSQ(Datos_anuales!$F$2:$F$48,Datos_anuales!$D$2:$D$48) | H3: =1-SUMSQ(Datos_anuales!$O$2:$O$48)/DEVSQ(Datos_anuales!$F$2:$F$48) | I3: =CORREL(Datos_anuales!$F$2:$F$48,Datos_anuales!$D$2:$D$48) | J3: =STEYX(Datos_anuales!$F$2:$F$48,Datos_anuales!$D$2:$D$48) | K3: ="Tmin = "&TEXT(C3,"0.00")&" − "&TEXT(E3,"0.00000")&"·Z"
A4: Tmed | B4: =COUNT(Datos_anuales!$G$2:$G$48) | C4: =INTERCEPT(Datos_anuales!$G$2:$G$48,Datos_anuales!$D$2:$D$48) | D4: =SLOPE(Datos_anuales!$G$2:$G$48,Datos_anuales!$D$2:$D$48) | E4: =-D4 | F4: =1000*E4 | G4: =RSQ(Datos_anuales!$G$2:$G$48,Datos_anuales!$D$2:$D$48) | H4: =1-SUMSQ(Datos_anuales!$T$2:$T$48)/DEVSQ(Datos_anuales!$G$2:$G$48) | I4: =CORREL(Datos_anuales!$G$2:$G$48,Datos_anuales!$D$2:$D$48) | J4: =STEYX(Datos_anuales!$G$2:$G$48,Datos_anuales!$D$2:$D$48) | K4: ="Tmed = "&TEXT(C4,"0.00")&" − "&TEXT(E4,"0.00000")&"·Z"
A6: Verificación (calculado en Python con numpy.polyfit)
A7: Variable | B7: n | C7: T0 (°C) | D7: α (°C/km) | E7: R²
A8: Tmax | B8: 47 | C8: 36.801 | D8: 7.282 | E8: 0.9822
A9: Tmin | B9: 47 | C9: 24.213 | D9: 5.654 | E9: 0.9638
A10: Tmed | B10: 47 | C10: 30.044 | D10: 6.399 | E10: 0.9863

Sheet Datos_mensuales
A1: Código | B1: Nombre | C1: Z (m) | D1: Tmax ENE | E1: Tmax FEB | F1: Tmax MAR | G1: Tmax ABR | H1: Tmax MAY | I1: Tmax JUN | J1: Tmax JUL | K1: Tmax AGO | L1: Tmax SEP | M1: Tmax OCT | N1: Tmax NOV | O1: Tmax DIC | P1: Tmin ENE | Q1: Tmin FEB | R1: Tmin MAR | S1: Tmin ABR | T1: Tmin MAY | U1: Tmin JUN | V1: Tmin JUL | W1: Tmin AGO | X1: Tmin SEP | Y1: Tmin OCT | Z1: Tmin NOV | AA1: Tmin DIC | AB1: Tmed ENE | AC1: Tmed FEB | AD1: Tmed MAR | AE1: Tmed ABR | AF1: Tmed MAY | AG1: Tmed JUN | AH1: Tmed JUL | AI1: Tmed AGO | AJ1: Tmed SEP | AK1: Tmed OCT | AL1: Tmed NOV | AM1: Tmed DIC
A2: 26175040 | B2: Tunez Hda | C2: 530 | D2: 33.415789 | E2: 34.05 | F2: 34.116667 | G2: 32.794737 | H2: 32.185 | I2: 32.505263 | J2: 33.057895 | K2: 33.463158 | L2: 32.736842 | M2: 31.994444 | N2: 31.9 | O2: 32.3 | P2: 19.114286 | Q2: 19.442857 | R2: 19.75 | S2: 20.022727 | T2: 19.943478 | U2: 19.673913 | V2: 19.204348 | W2: 19.217391 | X2: 19.309091 | Y2: 19.386364 | Z2: 19.647619 | AA2: 19.404762 | AB2: 26.143478 | AC2: 26.990909 | AD2: 27.017391 | AE2: 26.356522 | AF2: 25.858333 | AG2: 25.833333 | AH2: 25.904167 | AI2: 26.129167 | AJ2: 25.6625 | AK2: 25.241667 | AL2: 25.356522 | AM2: 25.4375
A3: 26225030 | B3: Cotove Hda | C3: 530 | D3: 35.489474 | E3: 36.044444 | F3: 35.586364 | G3: 34.909524 | H3: 33.934783 | I3: 33.64 | J3: 34.21 | K3: 34.761111 | L3: 34.085714 | M3: 33.515 | N3: 33.357895 | O3: 34.086364 | P3: 20.138095 | Q3: 20.73913 | R3: 20.784615 | S3: 20.966667 | T3: 20.833333 | U3: 20.608696 | V3: 20.368 | W3: 20.347826 | X3: 20.161538 | Y3: 20.364 | Z3: 20.203846 | AA3: 20.223077 | AB3: 27.852174 | AC3: 28.372727 | AD3: 28.423077 | AE3: 27.488 | AF3: 26.684 | AG3: 26.564 | AH3: 26.76087 | AI3: 27.108 | AJ3: 26.408696 | AK3: 25.966667 | AL3: 26.3 | AM3: 26.776923
A4: 26115040 | B4: Cent Admo La Union | C4: 920 | D4: 31.1 | E4: 31.558333 | F4: 31.379167 | G4: 30.429167 | H4: 29.745833 | I4: 30.1625 | J4: 30.970833 | K4: 31.766667 | L4: 30.958333 | M4: 29.983333 | N4: 29.4375 | O4: 30.054167 | P4: 18.573333 | Q4: 18.75 | R4: 19.08 | S4: 19.333333 | T4: 19.246667 | U4: 18.766667 | V4: 18.306667 | W4: 18.323333 | X4: 18.516667 | Y4: 18.803333 | Z4: 18.863333 | AA4: 18.713333 | AB4: 24.4 | AC4: 24.803333 | AD4: 24.85 | AE4: 24.433333 | AF4: 24.143333 | AG4: 24.116667 | AH4: 24.383333 | AI4: 24.683333 | AJ4: 24.306667 | AK4: 23.8 | AL4: 23.736667 | AM4: 23.993333
A5: 26105110 | B5: Ing Riopaila | C5: 941 | D5: 31.411111 | E5: 31.9 | F5: 31.255556 | G5: 30.89375 | H5: 30.616667 | I5: 30.688889 | J5: 31.51875 | K5: 31.982353 | L5: 31.4 | M5: 30.705882 | N5: 30.316667 | O5: 30.633333 | P5: 18.033333 | Q5: 18.155556 | R5: 18.416667 | S5: 18.75 | T5: 18.738889 | U5: 18.311111 | V5: 18.088235 | W5: 18.0625 | X5: 18.129412 | Y5: 18.294118 | Z5: 18.488889 | AA5: 18.327778 | AB5: 24.5 | AC5: 24.946667 | AD5: 24.6625 | AE5: 24.225 | AF5: 24.106667 | AG5: 24.126667 | AH5: 24.313333 | AI5: 24.528571 | AJ5: 24.39375 | AK5: 24.1 | AL5: 23.975 | AM5: 24.025
A6: 26085120 | B6: Base Aerea MFS | C6: 954 | D6: 30.233333 | E6: 30.35 | F6: 30.3 | G6: 29.776923 | H6: 29.508333 | I6: 29.4 | J6: 30.223077 | K6: 30.992308 | L6: 30.4 | M6: 29.761538 | N6: 28.969231 | O6: 29.118182 | P6: 19.692308 | Q6: 19.738462 | R6: 19.807692 | S6: 19.884615 | T6: 19.9 | U6: 19.642857 | V6: 19.414286 | W6: 19.485714 | X6: 19.521429 | Y6: 19.535714 | Z6: 19.557143 | AA6: 19.709091 | AB6: 25.284 | AC6: 25.412 | AD6: 25.408 | AE6: 25.036 | AF6: 25.18 | AG6: 25.108333 | AH6: 25.421739 | AI6: 25.803846 | AJ6: 25.492308 | AK6: 24.808696 | AL6: 24.595652 | AM6: 24.617391
A7: 26105160 | B7: Apto Farfan | C7: 955 | D7: 30.2 | E7: 30.57 | F7: 30.466667 | G7: 29.7 | H7: 29.37 | I7: 29.633333 | J7: 30.32 | K7: 30.763333 | L7: 30.24 | M7: 29.293103 | N7: 28.986207 | O7: 29.382759 | P7: 18.440741 | Q7: 18.582143 | R7: 18.755556 | S7: 18.892593 | T7: 18.814286 | U7: 18.453571 | V7: 17.911111 | W7: 18.146429 | X7: 18.323077 | Y7: 18.381481 | Z7: 18.377778 | AA7: 18.380769 | AB7: 24.06 | AC7: 24.34 | AD7: 24.293333 | AE7: 23.946667 | AF7: 23.789655 | AG7: 23.703448 | AH7: 24.096552 | AI7: 24.233333 | AJ7: 23.993333 | AK7: 23.368966 | AL7: 23.137931 | AM7: 23.52069
A8: 26075040 | B8: Apto A Bonilla | C8: 961 | D8: 29.943333 | E8: 30.2 | F8: 30.086667 | G8: 29.48 | H8: 29.29 | I8: 29.453333 | J8: 30.143333 | K8: 30.703333 | L8: 30.183333 | M8: 29.23 | N8: 28.936667 | O8: 29.223333 | P8: 18.853333 | Q8: 19.023333 | R8: 19.21 | S8: 19.233333 | T8: 19.246667 | U8: 18.886667 | V8: 18.436667 | W8: 18.546667 | X8: 18.673333 | Y8: 18.783333 | Z8: 18.81 | AA8: 18.9 | AB8: 23.953333 | AC8: 24.23 | AD8: 24.206667 | AE8: 23.916667 | AF8: 23.913333 | AG8: 23.91 | AH8: 24.103333 | AI8: 24.323333 | AJ8: 24.053333 | AK8: 23.523333 | AL8: 23.393333 | AM8: 23.57
A9: 26135100 | B9: Bohemia La | C9: 970 | D9: 30.584 | E9: 30.95 | F9: 30.648 | G9: 29.872 | H9: 29.56 | I9: 29.656 | J9: 30.332 | K9: 30.72 | L9: 30.464 | M9: 29.484 | N9: 29.208 | O9: 29.558333 | P9: 19.063333 | Q9: 19.303333 | R9: 19.346667 | S9: 19.506667 | T9: 19.45 | U9: 19.13 | V9: 18.75 | W9: 18.723333 | X9: 18.81 | Y9: 18.886667 | Z9: 19.06 | AA9: 19.1 | AB9: 24.09 | AC9: 24.263333 | AD9: 24.24 | AE9: 23.916667 | AF9: 23.773333 | AG9: 23.88 | AH9: 24.136667 | AI9: 24.36 | AJ9: 23.933333 | AK9: 23.433333 | AL9: 23.353333 | AM9: 23.668966
A10: 26095230 | B10: Vinculo El | C10: 979 | D10: 30.161905 | E10: 30.27619 | F10: 30.438095 | G10: 29.5 | H10: 29.409524 | I10: 29.37619 | J10: 29.92 | K10: 30.48 | L10: 30.235 | M10: 29.633333 | N10: 29.3 | O10: 29.631579 | P10: 18.570833 | Q10: 18.733333 | R10: 19.0625 | S10: 19.116667 | T10: 19.195833 | U10: 18.854167 | V10: 18.683333 | W10: 18.6875 | X10: 18.7125 | Y10: 18.6625 | Z10: 18.691667 | AA10: 18.675 | AB10: 23.684615 | AC10: 23.981481 | AD10: 23.974074 | AE10: 23.57037 | AF10: 23.507407 | AG10: 23.359259 | AH10: 23.681481 | AI10: 23.977778 | AJ10: 23.803704 | AK10: 23.240741 | AL10: 23.077778 | AM10: 23.255556
A11: 26055070 | B11: Univ del Valle | C11: 985 | D11: 29.97 | E11: 30.256667 | F11: 30.166667 | G11: 29.593333 | H11: 29.393333 | I11: 29.566667 | J11: 30.25 | K11: 31.09 | L11: 30.686667 | M11: 29.53 | N11: 28.963333 | O11: 29.16 | P11: 19.38 | Q11: 19.46 | R11: 19.576667 | S11: 19.586667 | T11: 19.616667 | U11: 19.16 | V11: 18.653333 | W11: 18.726667 | X11: 18.97 | Y11: 19.056667 | Z11: 19.21 | AA11: 19.436667 | AB11: 24.527586 | AC11: 24.717241 | AD11: 24.66 | AE11: 24.363333 | AF11: 24.356667 | AG11: 24.39 | AH11: 24.683333 | AI11: 25.12 | AJ11: 24.82 | AK11: 24.143333 | AL11: 23.843333 | AM11: 24.116667
A12: 26065010 | B12: Ing Cauca | C12: 1000 | D12: 29.991304 | E12: 30.273913 | F12: 30.269565 | G12: 29.582609 | H12: 29.391304 | I12: 29.558333 | J12: 29.9125 | K12: 30.345833 | L12: 30.104167 | M12: 29.4375 | N12: 29.034783 | O12: 29.421739 | P12: 18.564 | Q12: 18.770833 | R12: 18.720833 | S12: 19.056522 | T12: 19.083333 | U12: 18.816 | V12: 18.216 | W12: 17.992308 | X12: 18.216667 | Y12: 18.486957 | Z12: 18.773913 | AA12: 18.747826 | AB12: 23.555172 | AC12: 23.735714 | AD12: 23.648276 | AE12: 23.389655 | AF12: 23.417241 | AG12: 23.476667 | AH12: 23.575862 | AI12: 23.836667 | AJ12: 23.536667 | AK12: 23.176667 | AL12: 22.936667 | AM12: 23.272414
A13: 26045010 | B13: Ing Bengala | C13: 1000 | D13: 29.972727 | E13: 30.290909 | F13: 30.181818 | G13: 29.580952 | H13: 29.634783 | I13: 29.695652 | J13: 30.243478 | K13: 30.613043 | L13: 30.286957 | M13: 29.53913 | N13: 29.173913 | O13: 29.482609 | P13: 18.042308 | Q13: 17.965385 | R13: 18.103846 | S13: 18.108 | T13: 18.265385 | U13: 17.946154 | V13: 17.453846 | W13: 17.526923 | X13: 17.726923 | Y13: 17.911538 | Z13: 17.980769 | AA13: 18.053846 | AB13: 24.139286 | AC13: 24.203571 | AD13: 24.082143 | AE13: 23.860714 | AF13: 23.967857 | AG13: 23.996429 | AH13: 24.171429 | AI13: 24.3 | AJ13: 24.139286 | AK13: 23.860714 | AL13: 23.792857 | AM13: 23.896429
... A48: 26155150 | B48: Brisas Las | C48: 4150 | D48: 8.5761905 | E48: 8.5238095 | F48: 8.6666667 | G48: 8.5380952 | H48: 8.4761905 | I48: 8.6857143 | J48: 8.615 | K48: 8.6428571 | L48: 8.2619048 | M48: 7.7285714 | N48: 7.9952381 | O48: 8.425 | P48: 0.76206897 | Q48: 0.97586207 | R48: 1.1551724 | S48: 1.7964286 | T48: 1.9464286 | U48: 1.5178571 | V48: 0.90357143 | W48: 0.92758621 | X48: 1.0482759 | Y48: 1.3103448 | Z48: 1.4793103 | AA48: 1.0137931 | AB48: 4.4068966 | AC48: 4.637931 | AD48: 4.7758621 | AE48: 4.9785714 | AF48: 5.1206897 | AG48: 4.8655172 | AH48: 4.5482759 | AI48: 4.5 | AJ48: 4.425 | AK48: 4.3758621 | AL48: 4.4413793 | AM48: 4.537931

Sheet Regresiones_mensuales
A1: Variable | B1: Mes | C1: n | D1: T0 (°C) | E1: α (°C/m) | F1: α (°C/km) | G1: R²
A2: Tmax | B2: ENE | C2: =COUNT(Datos_mensuales!$D$2:$D$48) | D2: =INTERCEPT(Datos_mensuales!$D$2:$D$48,Datos_mensuales!$C$2:$C$48) | E2: =-SLOPE(Datos_mensuales!$D$2:$D$48,Datos_mensuales!$C$2:$C$48) | F2: =1000*E2 | G2: =RSQ(Datos_mensuales!$D$2:$D$48,Datos_mensuales!$C$2:$C$48)
A3: Tmax | B3: FEB | C3: =COUNT(Datos_mensuales!$E$2:$E$48) | D3: =INTERCEPT(Datos_mensuales!$E$2:$E$48,Datos_mensuales!$C$2:$C$48) | E3: =-SLOPE(Datos_mensuales!$E$2:$E$48,Datos_mensuales!$C$2:$C$48) | F3: =1000*E3 | G3: =RSQ(Datos_mensuales!$E$2:$E$48,Datos_mensuales!$C$2:$C$48)
A4: Tmax | B4: MAR | C4: =COUNT(Datos_mensuales!$F$2:$F$48) | D4: =INTERCEPT(Datos_mensuales!$F$2:$F$48,Datos_mensuales!$C$2:$C$48) | E4: =-SLOPE(Datos_mensuales!$F$2:$F$48,Datos_mensuales!$C$2:$C$48) | F4: =1000*E4 | G4: =RSQ(Datos_mensuales!$F$2:$F$48,Datos_mensuales!$C$2:$C$48)
A5: Tmax | B5: ABR | C5: =COUNT(Datos_mensuales!$G$2:$G$48) | D5: =INTERCEPT(Datos_mensuales!$G$2:$G$48,Datos_mensuales!$C$2:$C$48) | E5: =-SLOPE(Datos_mensuales!$G$2:$G$48,Datos_mensuales!$C$2:$C$48) | F5: =1000*E5 | G5: =RSQ(Datos_mensuales!$G$2:$G$48,Datos_mensuales!$C$2:$C$48)
A6: Tmax | B6: MAY | C6: =COUNT(Datos_mensuales!$H$2:$H$48) | D6: =INTERCEPT(Datos_mensuales!$H$2:$H$48,Datos_mensuales!$C$2:$C$48) | E6: =-SLOPE(Datos_mensuales!$H$2:$H$48,Datos_mensuales!$C$2:$C$48) | F6: =1000*E6 | G6: =RSQ(Datos_mensuales!$H$2:$H$48,Datos_mensuales!$C$2:$C$48)
A7: Tmax | B7: JUN | C7: =COUNT(Datos_mensuales!$I$2:$I$48) | D7: =INTERCEPT(Datos_mensuales!$I$2:$I$48,Datos_mensuales!$C$2:$C$48) | E7: =-SLOPE(Datos_mensuales!$I$2:$I$48,Datos_mensuales!$C$2:$C$48) | F7: =1000*E7 | G7: =RSQ(Datos_mensuales!$I$2:$I$48,Datos_mensuales!$C$2:$C$48)
A8: Tmax | B8: JUL | C8: =COUNT(Datos_mensuales!$J$2:$J$48) | D8: =INTERCEPT(Datos_mensuales!$J$2:$J$48,Datos_mensuales!$C$2:$C$48) | E8: =-SLOPE(Datos_mensuales!$J$2:$J$48,Datos_mensuales!$C$2:$C$48) | F8: =1000*E8 | G8: =RSQ(Datos_mensuales!$J$2:$J$48,Datos_mensuales!$C$2:$C$48)
A9: Tmax | B9: AGO | C9: =COUNT(Datos_mensuales!$K$2:$K$48) | D9: =INTERCEPT(Datos_mensuales!$K$2:$K$48,Datos_mensuales!$C$2:$C$48) | E9: =-SLOPE(Datos_mensuales!$K$2:$K$48,Datos_mensuales!$C$2:$C$48) | F9: =1000*E9 | G9: =RSQ(Datos_mensuales!$K$2:$K$48,Datos_mensuales!$C$2:$C$48)
A10: Tmax | B10: SEP | C10: =COUNT(Datos_mensuales!$L$2:$L$48) | D10: =INTERCEPT(Datos_mensuales!$L$2:$L$48,Datos_mensuales!$C$2:$C$48) | E10: =-SLOPE(Datos_mensuales!$L$2:$L$48,Datos_mensuales!$C$2:$C$48) | F10: =1000*E10 | G10: =RSQ(Datos_mensuales!$L$2:$L$48,Datos_mensuales!$C$2:$C$48)
A11: Tmax | B11: OCT | C11: =COUNT(Datos_mensuales!$M$2:$M$48) | D11: =INTERCEPT(Datos_mensuales!$M$2:$M$48,Datos_mensuales!$C$2:$C$48) | E11: =-SLOPE(Datos_mensuales!$M$2:$M$48,Datos_mensuales!$C$2:$C$48) | F11: =1000*E11 | G11: =RSQ(Datos_mensuales!$M$2:$M$48,Datos_mensuales!$C$2:$C$48)
A12: Tmax | B12: NOV | C12: =COUNT(Datos_mensuales!$N$2:$N$48) | D12: =INTERCEPT(Datos_mensuales!$N$2:$N$48,Datos_mensuales!$C$2:$C$48) | E12: =-SLOPE(Datos_mensuales!$N$2:$N$48,Datos_mensuales!$C$2:$C$48) | F12: =1000*E12 | G12: =RSQ(Datos_mensuales!$N$2:$N$48,Datos_mensuales!$C$2:$C$48)
A13: Tmax | B13: DIC | C13: =COUNT(Datos_mensuales!$O$2:$O$48) | D13: =INTERCEPT(Datos_mensuales!$O$2:$O$48,Datos_mensuales!$C$2:$C$48) | E13: =-SLOPE(Datos_mensuales!$O$2:$O$48,Datos_mensuales!$C$2:$C$48) | F13: =1000*E13 | G13: =RSQ(Datos_mensuales!$O$2:$O$48,Datos_mensuales!$C$2:$C$48)
A14: Tmin | B14: ENE | C14: =COUNT(Datos_mensuales!$P$2:$P$48) | D14: =INTERCEPT(Datos_mensuales!$P$2:$P$48,Datos_mensuales!$C$2:$C$48) | E14: =-SLOPE(Datos_mensuales!$P$2:$P$48,Datos_mensuales!$C$2:$C$48) | F14: =1000*E14 | G14: =RSQ(Datos_mensuales!$P$2:$P$48,Datos_mensuales!$C$2:$C$48)
A15: Tmin | B15: FEB | C15: =COUNT(Datos_mensuales!$Q$2:$Q$48) | D15: =INTERCEPT(Datos_mensuales!$Q$2:$Q$48,Datos_mensuales!$C$2:$C$48) | E15: =-SLOPE(Datos_mensuales!$Q$2:$Q$48,Datos_mensuales!$C$2:$C$48) | F15: =1000*E15 | G15: =RSQ(Datos_mensuales!$Q$2:$Q$48,Datos_mensuales!$C$2:$C$48)
A16: Tmin | B16: MAR | C16: =COUNT(Datos_mensuales!$R$2:$R$48) | D16: =INTERCEPT(Datos_mensuales!$R$2:$R$48,Datos_mensuales!$C$2:$C$48) | E16: =-SLOPE(Datos_mensuales!$R$2:$R$48,Datos_mensuales!$C$2:$C$48) | F16: =1000*E16 | G16: =RSQ(Datos_mensuales!$R$2:$R$48,Datos_mensuales!$C$2:$C$48)
A17: Tmin | B17: ABR | C17: =COUNT(Datos_mensuales!$S$2:$S$48) | D17: =INTERCEPT(Datos_mensuales!$S$2:$S$48,Datos_mensuales!$C$2:$C$48) | E17: =-SLOPE(Datos_mensuales!$S$2:$S$48,Datos_mensuales!$C$2:$C$48) | F17: =1000*E17 | G17: =RSQ(Datos_mensuales!$S$2:$S$48,Datos_mensuales!$C$2:$C$48)
A18: Tmin | B18: MAY | C18: =COUNT(Datos_mensuales!$T$2:$T$48) | D18: =INTERCEPT(Datos_mensuales!$T$2:$T$48,Datos_mensuales!$C$2:$C$48) | E18: =-SLOPE(Datos_mensuales!$T$2:$T$48,Datos_mensuales!$C$2:$C$48) | F18: =1000*E18 | G18: =RSQ(Datos_mensuales!$T$2:$T$48,Datos_mensuales!$C$2:$C$48)
A19: Tmin | B19: JUN | C19: =COUNT(Datos_mensuales!$U$2:$U$48) | D19: =INTERCEPT(Datos_mensuales!$U$2:$U$48,Datos_mensuales!$C$2:$C$48) | E19: =-SLOPE(Datos_mensuales!$U$2:$U$48,Datos_mensuales!$C$2:$C$48) | F19: =1000*E19 | G19: =RSQ(Datos_mensuales!$U$2:$U$48,Datos_mensuales!$C$2:$C$48)
A20: Tmin | B20: JUL | C20: =COUNT(Datos_mensuales!$V$2:$V$48) | D20: =INTERCEPT(Datos_mensuales!$V$2:$V$48,Datos_mensuales!$C$2:$C$48) | E20: =-SLOPE(Datos_mensuales!$V$2:$V$48,Datos_mensuales!$C$2:$C$48) | F20: =1000*E20 | G20: =RSQ(Datos_mensuales!$V$2:$V$48,Datos_mensuales!$C$2:$C$48)
A21: Tmin | B21: AGO | C21: =COUNT(Datos_mensuales!$W$2:$W$48) | D21: =INTERCEPT(Datos_mensuales!$W$2:$W$48,Datos_mensuales!$C$2:$C$48) | E21: =-SLOPE(Datos_mensuales!$W$2:$W$48,Datos_mensuales!$C$2:$C$48) | F21: =1000*E21 | G21: =RSQ(Datos_mensuales!$W$2:$W$48,Datos_mensuales!$C$2:$C$48)
A22: Tmin | B22: SEP | C22: =COUNT(Datos_mensuales!$X$2:$X$48) | D22: =INTERCEPT(Datos_mensuales!$X$2:$X$48,Datos_mensuales!$C$2:$C$48) | E22: =-SLOPE(Datos_mensuales!$X$2:$X$48,Datos_mensuales!$C$2:$C$48) | F22: =1000*E22 | G22: =RSQ(Datos_mensuales!$X$2:$X$48,Datos_mensuales!$C$2:$C$48)
A23: Tmin | B23: OCT | C23: =COUNT(Datos_mensuales!$Y$2:$Y$48) | D23: =INTERCEPT(Datos_mensuales!$Y$2:$Y$48,Datos_mensuales!$C$2:$C$48) | E23: =-SLOPE(Datos_mensuales!$Y$2:$Y$48,Datos_mensuales!$C$2:$C$48) | F23: =1000*E23 | G23: =RSQ(Datos_mensuales!$Y$2:$Y$48,Datos_mensuales!$C$2:$C$48)
A24: Tmin | B24: NOV | C24: =COUNT(Datos_mensuales!$Z$2:$Z$48) | D24: =INTERCEPT(Datos_mensuales!$Z$2:$Z$48,Datos_mensuales!$C$2:$C$48) | E24: =-SLOPE(Datos_mensuales!$Z$2:$Z$48,Datos_mensuales!$C$2:$C$48) | F24: =1000*E24 | G24: =RSQ(Datos_mensuales!$Z$2:$Z$48,Datos_mensuales!$C$2:$C$48)
A25: Tmin | B25: DIC | C25: =COUNT(Datos_mensuales!$AA$2:$AA$48) | D25: =INTERCEPT(Datos_mensuales!$AA$2:$AA$48,Datos_mensuales!$C$2:$C$48) | E25: =-SLOPE(Datos_mensuales!$AA$2:$AA$48,Datos_mensuales!$C$2:$C$48) | F25: =1000*E25 | G25: =RSQ(Datos_mensuales!$AA$2:$AA$48,Datos_mensuales!$C$2:$C$48)
A26: Tmed | B26: ENE | C26: =COUNT(Datos_mensuales!$AB$2:$AB$48) | D26: =INTERCEPT(Datos_mensuales!$AB$2:$AB$48,Datos_mensuales!$C$2:$C$48) | E26: =-SLOPE(Datos_mensuales!$AB$2:$AB$48,Datos_mensuales!$C$2:$C$48) | F26: =1000*E26 | G26: =RSQ(Datos_mensuales!$AB$2:$AB$48,Datos_mensuales!$C$2:$C$48)
A27: Tmed | B27: FEB | C27: =COUNT(Datos_mensuales!$AC$2:$AC$48) | D27: =INTERCEPT(Datos_mensuales!$AC$2:$AC$48,Datos_mensuales!$C$2:$C$48) | E27: =-SLOPE(Datos_mensuales!$AC$2:$AC$48,Datos_mensuales!$C$2:$C$48) | F27: =1000*E27 | G27: =RSQ(Datos_mensuales!$AC$2:$AC$48,Datos_mensuales!$C$2:$C$48)
A28: Tmed | B28: MAR | C28: =COUNT(Datos_mensuales!$AD$2:$AD$48) | D28: =INTERCEPT(Datos_mensuales!$AD$2:$AD$48,Datos_mensuales!$C$2:$C$48) | E28: =-SLOPE(Datos_mensuales!$AD$2:$AD$48,Datos_mensuales!$C$2:$C$48) | F28: =1000*E28 | G28: =RSQ(Datos_mensuales!$AD$2:$AD$48,Datos_mensuales!$C$2:$C$48)
A29: Tmed | B29: ABR | C29: =COUNT(Datos_mensuales!$AE$2:$AE$48) | D29: =INTERCEPT(Datos_mensuales!$AE$2:$AE$48,Datos_mensuales!$C$2:$C$48) | E29: =-SLOPE(Datos_mensuales!$AE$2:$AE$48,Datos_mensuales!$C$2:$C$48) | F29: =1000*E29 | G29: =RSQ(Datos_mensuales!$AE$2:$AE$48,Datos_mensuales!$C$2:$C$48)
A30: Tmed | B30: MAY | C30: =COUNT(Datos_mensuales!$AF$2:$AF$48) | D30: =INTERCEPT(Datos_mensuales!$AF$2:$AF$48,Datos_mensuales!$C$2:$C$48) | E30: =-SLOPE(Datos_mensuales!$AF$2:$AF$48,Datos_mensuales!$C$2:$C$48) | F30: =1000*E30 | G30: =RSQ(Datos_mensuales!$AF$2:$AF$48,Datos_mensuales!$C$2:$C$48)
A31: Tmed | B31: JUN | C31: =COUNT(Datos_mensuales!$AG$2:$AG$48) | D31: =INTERCEPT(Datos_mensuales!$AG$2:$AG$48,Datos_mensuales!$C$2:$C$48) | E31: =-SLOPE(Datos_mensuales!$AG$2:$AG$48,Datos_mensuales!$C$2:$C$48) | F31: =1000*E31 | G31: =RSQ(Datos_mensuales!$AG$2:$AG$48,Datos_mensuales!$C$2:$C$48)
A32: Tmed | B32: JUL | C32: =COUNT(Datos_mensuales!$AH$2:$AH$48) | D32: =INTERCEPT(Datos_mensuales!$AH$2:$AH$48,Datos_mensuales!$C$2:$C$48) | E32: =-SLOPE(Datos_mensuales!$AH$2:$AH$48,Datos_mensuales!$C$2:$C$48) | F32: =1000*E32 | G32: =RSQ(Datos_mensuales!$AH$2:$AH$48,Datos_mensuales!$C$2:$C$48)
A33: Tmed | B33: AGO | C33: =COUNT(Datos_mensuales!$AI$2:$AI$48) | D33: =INTERCEPT(Datos_mensuales!$AI$2:$AI$48,Datos_mensuales!$C$2:$C$48) | E33: =-SLOPE(Datos_mensuales!$AI$2:$AI$48,Datos_mensuales!$C$2:$C$48) | F33: =1000*E33 | G33: =RSQ(Datos_mensuales!$AI$2:$AI$48,Datos_mensuales!$C$2:$C$48)
A34: Tmed | B34: SEP | C34: =COUNT(Datos_mensuales!$AJ$2:$AJ$48) | D34: =INTERCEPT(Datos_mensuales!$AJ$2:$AJ$48,Datos_mensuales!$C$2:$C$48) | E34: =-SLOPE(Datos_mensuales!$AJ$2:$AJ$48,Datos_mensuales!$C$2:$C$48) | F34: =1000*E34 | G34: =RSQ(Datos_mensuales!$AJ$2:$AJ$48,Datos_mensuales!$C$2:$C$48)
A35: Tmed | B35: OCT | C35: =COUNT(Datos_mensuales!$AK$2:$AK$48) | D35: =INTERCEPT(Datos_mensuales!$AK$2:$AK$48,Datos_mensuales!$C$2:$C$48) | E35: =-SLOPE(Datos_mensuales!$AK$2:$AK$48,Datos_mensuales!$C$2:$C$48) | F35: =1000*E35 | G35: =RSQ(Datos_mensuales!$AK$2:$AK$48,Datos_mensuales!$C$2:$C$48)
A36: Tmed | B36: NOV | C36: =COUNT(Datos_mensuales!$AL$2:$AL$48) | D36: =INTERCEPT(Datos_mensuales!$AL$2:$AL$48,Datos_mensuales!$C$2:$C$48) | E36: =-SLOPE(Datos_mensuales!$AL$2:$AL$48,Datos_mensuales!$C$2:$C$48) | F36: =1000*E36 | G36: =RSQ(Datos_mensuales!$AL$2:$AL$48,Datos_mensuales!$C$2:$C$48)
A37: Tmed | B37: DIC | C37: =COUNT(Datos_mensuales!$AM$2:$AM$48) | D37: =INTERCEPT(Datos_mensuales!$AM$2:$AM$48,Datos_mensuales!$C$2:$C$48) | E37: =-SLOPE(Datos_mensuales!$AM$2:$AM$48,Datos_mensuales!$C$2:$C$48) | F37: =1000*E37 | G37: =RSQ(Datos_mensuales!$AM$2:$AM$48,Datos_mensuales!$C$2:$C$48)

Sheet Sensibilidad_atipicos
A1: Variable | B1: Atípicos | C1: n con todos | D1: α con todos (°C/km) | E1: T0 con todos (°C) | F1: R² con todos | G1: n sin atípicos | H1: α sin atípicos (°C/km) | I1: T0 sin atípicos (°C) | J1: R² sin atípicos
A2: Tmax | B2: Cedral El, Brisas Las | C2: 47 | D2: 7.2824 | E2: 36.8012 | F2: 0.9822 | G2: 45 | H2: 7.5151 | I2: 37.1486 | J2: 0.9841
A3: Tmin | B3: San Felix | C3: 47 | D3: 5.6544 | E3: 24.213 | F3: 0.9638 | G3: 46 | H3: 5.5041 | I3: 24.0441 | J3: 0.9722
A4: Tmed | B4: San Felix, Brisas Las | C4: 47 | D4: 6.3989 | E4: 30.0437 | F4: 0.9863 | G4: 45 | H4: 6.4871 | I4: 30.1806 | J4: 0.9847

Sheet Diagramas
