Workbook

Sheet Metodologia
A1: PUNTO 8 — CARACTERIZACIÓN DE LOS CAUDALES OBSERVADOS
A2: Cuenca del río Cauca hasta la presa de Hidroituango (área 35 992 km², DEM GLO-30 90 m).
A4: Fuente de caudales: IDEAM, archivo nacional HidrologiaNacionalDiaria.zip (actualizado 12/08/2026), variable Q_MEDIA_D (caudal medio diario, m³/s).
A5: Ubicación: Catálogo Nacional de Estaciones del IDEAM (datos.gov.co, dataset hp9r-jxuu).
A7: Criterio de validación (≥ 15 años de información):
A8: · Mes válido: ≥ 80 % de los días con dato; el caudal mensual es el promedio de los días.
A9: · Año válido: 12 meses válidos.
A10: · Estación validada: ≥ 15 años válidos en el periodo común 1981–2010 (periodo de la climatología IDEAM).
A11: · No cumplieron: Pte. Pescadero y Olaya (10 años), Mediacanoa (7), La Salvajina (termina en 1980); Anacaro no tiene serie de caudal.
A13: Área de drenaje: delimitada con el DEM Copernicus GLO-30 remuestreado a 90 m (EPSG:3116), relleno de depresiones Priority-Flood + ε y direcciones de flujo D8.
A14: El punto de cada estación se ajusta a la celda más cercana del cauce con área acumulada ≥ 1000 km² (columna 'Ajuste al cauce').
A15: La Pintada se ajusta al cauce aguas arriba de la desembocadura del río Arma: entre Irra y La Pintada el caudal sólo aumenta 26 m³/s, mientras el Arma aporta ~42 m³/s (Quitasueño).
... A22: Celdas amarillas = datos de entrada; el resto son fórmulas de Excel.

Sheet Estaciones
A1: Código | B1: Estación | C1: Corriente | D1: Rol | E1: Categoría | F1: Estado actual | G1: Departamento | H1: Municipio | I1: Latitud (°) | J1: Longitud (°) | K1: Este 3116 (m) | L1: Norte 3116 (m) | M1: Altitud (m s.n.m.) | N1: Área de drenaje (km²) | O1: % de la cuenca | P1: Ajuste al cauce (m) | Q1: Inicio registro | R1: Fin registro | S1: Años de registro | T1: % días con dato | U1: Años válidos 1981–2010 | V1: ¿>15 años?
A2: 26027010 | B2: La Balsa | C2: CAUCA | D2: cabecera | E2: Limnigráfica | F2: Activa | G2: Cauca | H2: Buenos Aires | I2: 3.091694 | J2: -76.599083 | K2: 719614.7 | L2: 833965.7 | M2: 987 | N2: 5075 | O2: =N2/35991.7749*100 | P2: 139 | Q2: 16803 | R2: 45757 | S2: =YEARFRAC(Q2,R2) | T2: 85.2 | U2: 22 | V2: =IF(U2>15,"Sí","No")
A3: 26067010 | B3: Juanchito | C3: CAUCA | D3: cuenca | E3: Limnigráfica | F3: Activa | G3: Valle Del Cauca | H3: Candelaria | I3: 3.451608 | J3: -76.475383 | K3: 733472.9 | L3: 873767.2 | M3: 950 | N3: 9344.2 | O3: =N3/35991.7749*100 | P3: 3399 | Q3: 16711 | R3: 46246 | S3: =YEARFRAC(Q3,R3) | T3: 83.9 | U3: 23 | V3: =IF(U3>15,"Sí","No")
A4: 26107070 | B4: La Victoria | C4: CAUCA | D4: cuenca | E4: Limnigráfica | F4: Activa | G4: Valle Del Cauca | H4: La Victoria | I4: 4.516667 | J4: -76.033333 | K4: 782908.2 | L4: 991496.9 | M4: 907 | N4: 16284.8 | O4: =N4/35991.7749*100 | P4: 4831 | Q4: 21551 | R4: 46242 | S4: =YEARFRAC(Q4,R4) | T4: 84 | U4: 24 | V4: =IF(U4>15,"Sí","No")
A5: 26177030 | B5: La Virginia | C5: CAUCA | D5: cuenca | E5: Limnigráfica | F5: Activa | G5: Risaralda | H5: La Virginia | I5: 4.8925 | J5: -75.882694 | K5: 799742 | L5: 1033034.5 | M5: 922 | N5: 20549.1 | O5: =N5/35991.7749*100 | P5: 1201 | Q5: 17076 | R5: 46246 | S5: =YEARFRAC(Q5,R5) | T5: 99.9 | U5: 29 | V5: =IF(U5>15,"Sí","No")
A6: 26167070 | B6: Irra | C6: CAUCA | D6: cuenca | E6: Limnigráfica | F6: En Mantenimiento | G6: Caldas | H6: Neira | I6: 5.268306 | J6: -75.664194 | K6: 824089.8 | L6: 1074546.8 | M6: 766 | N6: 24571.2 | O6: =N6/35991.7749*100 | P6: 267 | Q6: 26299 | R6: 46246 | S6: =YEARFRAC(Q6,R6) | T6: 95.7 | U6: 27 | V6: =IF(U6>15,"Sí","No")
A7: 26187110 | B7: La Pintada | C7: CAUCA | D7: cuenca | E7: Limnimétrica | F7: Activa | G7: Antioquia | H7: La Pintada | I7: 5.741478 | J7: -75.600564 | K7: 831279.5 | L7: 1126873 | M7: 620 | N7: 26443.1 | O7: =N7/35991.7749*100 | P7: 452 | Q7: 23743 | R7: 46245 | S7: =YEARFRAC(Q7,R7) | T7: 99.3 | U7: 30 | V7: =IF(U7>15,"Sí","No")
A8: 26207030 | B8: Puente Iglesias | C8: CAUCA | D8: cuenca | E8: Limnigráfica | F8: Activa | G8: Antioquia | H8: Fredonia | I8: 5.829944 | J8: -75.7055 | K8: 819680 | L8: 1136692 | M8: 655 | N8: 29005 | O8: =N8/35991.7749*100 | P8: 36 | Q8: 28856 | R8: 46245 | S8: =YEARFRAC(Q8,R8) | T8: 92.7 | U8: 23 | V8: =IF(U8>15,"Sí","No")
A9: 26207080 | B9: Bolombolo | C9: CAUCA | D9: cuenca | E9: Limnigráfica | F9: Activa | G9: Antioquia | H9: Venecia | I9: 5.97 | J9: -75.84 | K9: 804827 | L9: 1152232.2 | M9: 1750 | N9: 30994.6 | O9: =N9/35991.7749*100 | P9: 123 | Q9: 26207 | R9: 46246 | S9: =YEARFRAC(Q9,R9) | T9: 99.4 | U9: 29 | V9: =IF(U9>15,"Sí","No")
A10: 26217050 | B10: Cañafisto | C10: CAUCA | D10: cuenca | E10: Limnigráfica | F10: Suspendida | G10: Antioquia | H10: Santa Fe De Antioquia | I10: 6.41725 | J10: -75.819619 | K10: 807246.9 | L10: 1201707.6 | M10: 1999 | N10: 32704.4 | O10: =N10/35991.7749*100 | P10: 65 | Q10: 28856 | R10: 45900 | S10: =YEARFRAC(Q10,R10) | T10: 74.2 | U10: 27 | V10: =IF(U10>15,"Sí","No")
A11: 26237040 | B11: Puerto Valdivia | C11: CAUCA | D11: salida | E11: Limnigráfica | F11: Activa | G11: Antioquia | H11: Valdivia | I11: 7.286994 | J11: -75.396731 | K11: 854310.5 | L11: 1297777.9 | M11: 110 | N11: 37267 | O11: =N11/35991.7749*100 | P11: 102 | Q11: 21916 | R11: 46246 | S11: =YEARFRAC(Q11,R11) | T11: 89.1 | U11: 19 | V11: =IF(U11>15,"Sí","No")

Sheet Q_mensual
A1: Fecha | B1: Año | C1: Mes | D1: La Balsa (26027010) | E1: Juanchito (26067010) | F1: La Victoria (26107070) | G1: La Virginia (26177030) | H1: Irra (26167070) | I1: La Pintada (26187110) | J1: Puente Iglesias (26207030) | K1: Bolombolo (26207080) | L1: Cañafisto (26217050) | M1: Puerto Valdivia (26237040)
A2: 29587 | B2: =YEAR(A2) | C2: =MONTH(A2) | D2: 167.703 | E2: 209.865 | F2: 270.745 | G2: 361.29 | H2: 431.419 | I2: 407.677 | J2: 472.968 | K2: 501.387 | L2: 559.935 | M2: 643.742
A3: 29618 | B3: =YEAR(A3) | C3: =MONTH(A3) | D3: 177.061 | E3: 231.311 | F3: 242.971 | G3: 309.464 | H3: 365.286 | I3: 344.75 | J3: 439.929 | K3: 429.857 | L3: 469.036 | M3: 514.857
A4: 29646 | B4: =YEAR(A4) | C4: =MONTH(A4) | D4: 208.935 | E4: 252.997 | F4: 297.877 | G4: 405.032 | H4: 496.419 | I4: 459.323 | J4: 477.065 | K4: 548.452 | L4: 601.581 | M4: 676.161
A5: 29677 | B5: =YEAR(A5) | C5: =MONTH(A5) | D5: 321.687 | E5: 399.09 | F5: 500.64 | G5: 681.633 | H5: 778.367 | I5: 814.033 | J5: 769.333 | K5: 906.733 | L5: 991.467 | M5: 1076.533
A6: 29707 | B6: =YEAR(A6) | C6: =MONTH(A6) | D6: 378.452 | E6: 528.835 | F6: 830.261 | G6: 1155.581 | H6: 1330.419 | I6: 1537.032 | J6: 1433.258 | K6: 1634 | L6: 1798.29 | M6: 1986.484
A7: 29738 | B7: =YEAR(A7) | C7: =MONTH(A7) | D7: 240.017 | E7: 338.837 | F7: 581.37 | G7: 796.2 | H7: 953.933 | I7: 1134.133 | J7: 1319.333 | K7: 1319.967 | L7: 1541.867 | M7: 1735.067
A8: 29768 | B8: =YEAR(A8) | C8: =MONTH(A8) | D8: 182.394 | E8: 252.765 | F8: 379.552 | G8: 505.226 | H8: 659.387 | I8: 695.613 | J8: 806.29 | K8: 865.097 | L8: 1008.742 | M8: 1303
A9: 29799 | B9: =YEAR(A9) | C9: =MONTH(A9) | D9: 106.013 | E9: 123.852 | F9: 176.077 | G9: 255.839 | H9: 303 | I9: 322.452 | J9: 424.29 | K9: 465.613 | L9: 547.387 | M9: 743.645
A10: 29830 | B10: =YEAR(A10) | C10: =MONTH(A10) | D10: 96.813 | E10: 115.44 | F10: 175.08 | G10: 281.267 | H10: 355.067 | I10: 430.733 | J10: 569.433 | K10: 643 | L10: 726.333 | M10: 991.067
A11: 29860 | B11: =YEAR(A11) | C11: =MONTH(A11) | D11: 115.003 | E11: 148.258 | F11: 207.087 | G11: 323.806 | H11: 425.032 | I11: 461.097 | J11: 581.065 | K11: 652.065 | L11: 730.903 | M11: 1055.774
A12: 29891 | B12: =YEAR(A12) | C12: =MONTH(A12) | D12: 298.803 | E12: 370.783 | F12: 496.943 | G12: 754.733 | H12: 910.1 | I12: 1054.5 | K12: 1232.133 | L12: 1321.467 | M12: 1734.067
A13: 29921 | B13: =YEAR(A13) | C13: =MONTH(A13) | D13: 277.355 | E13: 374.355 | F13: 542.168 | G13: 720.129 | H13: 846.71 | I13: 916.258 | K13: 1072.161 | L13: 1162.581 | M13: 1339.677
A14: 29952 | B14: =YEAR(A14) | C14: =MONTH(A14) | D14: 361.413 | E14: 463.145 | F14: 640.568 | G14: 905.452 | H14: 1106.519 | I14: 1184.161 | J14: 1171.71 | K14: 1288.129 | L14: 1355.774 | M14: 1380.613
A15: 29983 | B15: =YEAR(A15) | C15: =MONTH(A15) | D15: 293.371 | E15: 365.479 | F15: 520.643 | G15: 678.536 | H15: 844.411 | I15: 910.25 | J15: 920.36 | K15: 1015.429 | L15: 1045.107 | M15: 1130.893
A16: 30011 | B16: =YEAR(A16) | C16: =MONTH(A16) | D16: 367.758 | E16: 451.913 | F16: 612.739 | G16: 766.097 | H16: 952.484 | I16: 977.194 | J16: 1024.556 | K16: 1048.355 | L16: 1109.548 | M16: 1109.387
A17: 30042 | B17: =YEAR(A17) | C17: =MONTH(A17) | D17: 393.683 | E17: 581.18 | F17: 800.013 | G17: 1062.8 | H17: 1428.933 | I17: 1330 | J17: 1378.296 | K17: 1635.6 | L17: 1607.333 | M17: 1631.933
A18: 30072 | B18: =YEAR(A18) | C18: =MONTH(A18) | D18: 411.355 | E18: 536.29 | F18: 747.677 | G18: 1055.548 | H18: 1482.935 | I18: 1413.581 | J18: 1443.241 | K18: 1801.935 | L18: 1831.194 | M18: 2067.71
A19: 30103 | B19: =YEAR(A19) | C19: =MONTH(A19) | D19: 216.78 | E19: 277.167 | F19: 484.323 | G19: 646.267 | I19: 831.067 | J19: 940.167 | K19: 1067.767 | L19: 1135.1 | M19: 1376.067
A20: 30133 | B20: =YEAR(A20) | C20: =MONTH(A20) | D20: 164.316 | E20: 181.681 | F20: 253.361 | G20: 334.161 | I20: 391.484 | J20: 486.76 | K20: 523.871 | L20: 556.548 | M20: 831.935
A21: 30164 | B21: =YEAR(A21) | C21: =MONTH(A21) | D21: 116.003 | E21: 120.619 | F21: 174.277 | G21: 227.258 | H21: 235.532 | I21: 270.548 | K21: 364.839 | L21: 365.452 | M21: 679.655
A22: 30195 | B22: =YEAR(A22) | C22: =MONTH(A22) | D22: 107.927 | E22: 114.513 | F22: 149.92 | G22: 205.267 | H22: 234.133 | I22: 256.133 | J22: 347.345 | K22: 361.1 | L22: 360.6 | M22: 713.1
A23: 30225 | B23: =YEAR(A23) | C23: =MONTH(A23) | D23: 193.435 | E23: 279.258 | F23: 380.419 | G23: 500.419 | H23: 693.645 | I23: 643.387 | J23: 753.207 | K23: 852.484 | L23: 911.806 | M23: 1184.032
A24: 30256 | B24: =YEAR(A24) | C24: =MONTH(A24) | D24: 277.073 | E24: 355.74 | F24: 505.2 | G24: 662.367 | H24: 946.6 | I24: 847.367 | J24: 929.036 | K24: 1050.8 | L24: 1105.1 | M24: 1250.067
A25: 30286 | B25: =YEAR(A25) | C25: =MONTH(A25) | D25: 306.371 | E25: 382.477 | F25: 521.297 | G25: 650.065 | H25: 915.323 | I25: 771.742 | J25: 785.323 | K25: 929.806 | L25: 955.935 | M25: 1051.871
A26: 30317 | B26: =YEAR(A26) | C26: =MONTH(A26) | D26: 174.258 | E26: 223.716 | F26: 306.258 | G26: 404.194 | H26: 508.161 | I26: 455.258 | J26: 492.677 | K26: 549.742 | L26: 596.774 | M26: 671.71
A27: 30348 | B27: =YEAR(A27) | C27: =MONTH(A27) | D27: 166.361 | E27: 193.011 | F27: 223.571 | G27: 295.179 | H27: 450.214 | I27: 327.821 | J27: 384.893 | K27: 403.107 | L27: 444 | M27: 510.786
A28: 30376 | B28: =YEAR(A28) | C28: =MONTH(A28) | D28: 171.952 | E28: 229.926 | F28: 266.284 | G28: 336.806 | H28: 388 | I28: 376.516 | J28: 446.548 | K28: 475 | L28: 509.774 | M28: 575.677
A29: 30407 | B29: =YEAR(A29) | C29: =MONTH(A29) | D29: 329.367 | E29: 503.753 | F29: 711.4 | G29: 920.5 | H29: 1224.433 | I29: 1081.1 | J29: 1180.933 | K29: 1289.333 | L29: 1344.467 | M29: 1369.967
A30: 30437 | B30: =YEAR(A30) | C30: =MONTH(A30) | D30: 250.781 | E30: 381.645 | F30: 587.777 | G30: 812.903 | H30: 1191.161 | I30: 973.452 | J30: 1049.097 | K30: 1208.29 | L30: 1308.935 | M30: 1378.258
A31: 30468 | B31: =YEAR(A31) | C31: =MONTH(A31) | D31: 182.797 | E31: 264.46 | F31: 399.333 | G31: 579.767 | H31: 769.867 | I31: 746.267 | J31: 815.483 | K31: 928.667 | L31: 993.3 | M31: 1115.467
A32: 30498 | B32: =YEAR(A32) | C32: =MONTH(A32) | D32: 110.348 | E32: 133.874 | F32: 192.068 | G32: 278.71 | H32: 320.161 | I32: 327.258 | J32: 426.867 | K32: 479.581 | L32: 537.774 | M32: 754.968
A33: 30529 | B33: =YEAR(A33) | C33: =MONTH(A33) | D33: 103.368 | E33: 115.468 | F33: 154.1 | G33: 215.968 | H33: 218.871 | I33: 253.516 | J33: 328.759 | K33: 386.258 | L33: 424.129 | M33: 679
... A45: 30895 | B45: =YEAR(A45) | C45: =MONTH(A45) | D45: 144.148 | E45: 178 | F45: 251.871 | G45: 397.323 | H45: 519.613 | I45: 587.742 | J45: 707.517 | K45: 832.935 | L45: 864 | M45: 1081.903
A46: 30926 | B46: =YEAR(A46) | C46: =MONTH(A46) | D46: 170.65 | E46: 248.433 | F46: 336.567 | G46: 497.9 | H46: 646.667 | I46: 733.433 | K46: 1024.7 | L46: 1064.433 | M46: 1243.267
A47: 30956 | B47: =YEAR(A47) | C47: =MONTH(A47) | D47: 294.932 | E47: 460.226 | F47: 566.581 | G47: 883.581 | H47: 1019.323 | I47: 1185.032 | J47: 1303.154 | K47: 1540.194 | L47: 1581.968 | M47: 1673.226
A48: 30987 | B48: =YEAR(A48) | C48: =MONTH(A48) | D48: 350.483 | E48: 615.767 | F48: 944 | G48: 1487.167 | H48: 1714.333 | I48: 1770 | J48: 1747.148 | K48: 2130.1 | L48: 2262.4 | M48: 2310.867
A49: 31017 | B49: =YEAR(A49) | C49: =MONTH(A49) | D49: 303.529 | E49: 444.29 | F49: 699.194 | G49: 943.935 | H49: 1099.355 | I49: 1133 | J49: 1201.111 | K49: 1394.484 | L49: 1433.903 | M49: 1473.129
A50: 31048 | B50: =YEAR(A50) | C50: =MONTH(A50) | D50: 275.39 | E50: 408.1 | F50: 529.145 | G50: 712.032 | H50: 860.581 | I50: 864.161 | J50: 978.323 | K50: 1065.387 | L50: 1057.452 | M50: 1081.516
A51: 31079 | B51: =YEAR(A51) | C51: =MONTH(A51) | D51: 174.993 | E51: 229.957 | F51: 320.746 | G51: 445.964 | H51: 553.464 | I51: 515.036 | J51: 605.786 | K51: 671.429 | L51: 681.607 | M51: 746.5
...

Sheet Q_anual
A1: Año | B1: La Balsa (26027010) | C1: Juanchito (26067010) | D1: La Victoria (26107070) | E1: La Virginia (26177030) | F1: Irra (26167070) | G1: La Pintada (26187110) | H1: Puente Iglesias (26207030) | I1: Bolombolo (26207080) | J1: Cañafisto (26217050) | K1: Puerto Valdivia (26237040)
A2: 1981 | B2: =IF(COUNT(Q_mensual!D2:D13)=12,AVERAGE(Q_mensual!D2:D13),"") | C2: =IF(COUNT(Q_mensual!E2:E13)=12,AVERAGE(Q_mensual!E2:E13),"") | D2: =IF(COUNT(Q_mensual!F2:F13)=12,AVERAGE(Q_mensual!F2:F13),"") | E2: =IF(COUNT(Q_mensual!G2:G13)=12,AVERAGE(Q_mensual!G2:G13),"") | F2: =IF(COUNT(Q_mensual!H2:H13)=12,AVERAGE(Q_mensual!H2:H13),"") | G2: =IF(COUNT(Q_mensual!I2:I13)=12,AVERAGE(Q_mensual!I2:I13),"") | H2: =IF(COUNT(Q_mensual!J2:J13)=12,AVERAGE(Q_mensual!J2:J13),"") | I2: =IF(COUNT(Q_mensual!K2:K13)=12,AVERAGE(Q_mensual!K2:K13),"") | ... K2: =IF(COUNT(Q_mensual!M2:M13)=12,AVERAGE(Q_mensual!M2:M13),"")
A3: 1982 | B3: =IF(COUNT(Q_mensual!D14:D25)=12,AVERAGE(Q_mensual!D14:D25),"") | C3: =IF(COUNT(Q_mensual!E14:E25)=12,AVERAGE(Q_mensual!E14:E25),"") | D3: =IF(COUNT(Q_mensual!F14:F25)=12,AVERAGE(Q_mensual!F14:F25),"") | E3: =IF(COUNT(Q_mensual!G14:G25)=12,AVERAGE(Q_mensual!G14:G25),"") | F3: =IF(COUNT(Q_mensual!H14:H25)=12,AVERAGE(Q_mensual!H14:H25),"") | G3: =IF(COUNT(Q_mensual!I14:I25)=12,AVERAGE(Q_mensual!I14:I25),"") | H3: =IF(COUNT(Q_mensual!J14:J25)=12,AVERAGE(Q_mensual!J14:J25),"") | I3: =IF(COUNT(Q_mensual!K14:K25)=12,AVERAGE(Q_mensual!K14:K25),"") | ... K3: =IF(COUNT(Q_mensual!M14:M25)=12,AVERAGE(Q_mensual!M14:M25),"")
A4: 1983 | B4: =IF(COUNT(Q_mensual!D26:D37)=12,AVERAGE(Q_mensual!D26:D37),"") | C4: =IF(COUNT(Q_mensual!E26:E37)=12,AVERAGE(Q_mensual!E26:E37),"") | D4: =IF(COUNT(Q_mensual!F26:F37)=12,AVERAGE(Q_mensual!F26:F37),"") | E4: =IF(COUNT(Q_mensual!G26:G37)=12,AVERAGE(Q_mensual!G26:G37),"") | F4: =IF(COUNT(Q_mensual!H26:H37)=12,AVERAGE(Q_mensual!H26:H37),"") | G4: =IF(COUNT(Q_mensual!I26:I37)=12,AVERAGE(Q_mensual!I26:I37),"") | H4: =IF(COUNT(Q_mensual!J26:J37)=12,AVERAGE(Q_mensual!J26:J37),"") | I4: =IF(COUNT(Q_mensual!K26:K37)=12,AVERAGE(Q_mensual!K26:K37),"") | ... K4: =IF(COUNT(Q_mensual!M26:M37)=12,AVERAGE(Q_mensual!M26:M37),"")
A5: 1984 | B5: =IF(COUNT(Q_mensual!D38:D49)=12,AVERAGE(Q_mensual!D38:D49),"") | C5: =IF(COUNT(Q_mensual!E38:E49)=12,AVERAGE(Q_mensual!E38:E49),"") | D5: =IF(COUNT(Q_mensual!F38:F49)=12,AVERAGE(Q_mensual!F38:F49),"") | E5: =IF(COUNT(Q_mensual!G38:G49)=12,AVERAGE(Q_mensual!G38:G49),"") | F5: =IF(COUNT(Q_mensual!H38:H49)=12,AVERAGE(Q_mensual!H38:H49),"") | G5: =IF(COUNT(Q_mensual!I38:I49)=12,AVERAGE(Q_mensual!I38:I49),"") | H5: =IF(COUNT(Q_mensual!J38:J49)=12,AVERAGE(Q_mensual!J38:J49),"") | I5: =IF(COUNT(Q_mensual!K38:K49)=12,AVERAGE(Q_mensual!K38:K49),"") | ... K5: =IF(COUNT(Q_mensual!M38:M49)=12,AVERAGE(Q_mensual!M38:M49),"")
A6: 1985 | B6: =IF(COUNT(Q_mensual!D50:D61)=12,AVERAGE(Q_mensual!D50:D61),"") | C6: =IF(COUNT(Q_mensual!E50:E61)=12,AVERAGE(Q_mensual!E50:E61),"") | D6: =IF(COUNT(Q_mensual!F50:F61)=12,AVERAGE(Q_mensual!F50:F61),"") | E6: =IF(COUNT(Q_mensual!G50:G61)=12,AVERAGE(Q_mensual!G50:G61),"") | F6: =IF(COUNT(Q_mensual!H50:H61)=12,AVERAGE(Q_mensual!H50:H61),"") | G6: =IF(COUNT(Q_mensual!I50:I61)=12,AVERAGE(Q_mensual!I50:I61),"") | H6: =IF(COUNT(Q_mensual!J50:J61)=12,AVERAGE(Q_mensual!J50:J61),"") | I6: =IF(COUNT(Q_mensual!K50:K61)=12,AVERAGE(Q_mensual!K50:K61),"") | ... K6: =IF(COUNT(Q_mensual!M50:M61)=12,AVERAGE(Q_mensual!M50:M61),"")
A7: 1986 | B7: =IF(COUNT(Q_mensual!D62:D73)=12,AVERAGE(Q_mensual!D62:D73),"") | C7: =IF(COUNT(Q_mensual!E62:E73)=12,AVERAGE(Q_mensual!E62:E73),"") | D7: =IF(COUNT(Q_mensual!F62:F73)=12,AVERAGE(Q_mensual!F62:F73),"") | E7: =IF(COUNT(Q_mensual!G62:G73)=12,AVERAGE(Q_mensual!G62:G73),"") | F7: =IF(COUNT(Q_mensual!H62:H73)=12,AVERAGE(Q_mensual!H62:H73),"") | G7: =IF(COUNT(Q_mensual!I62:I73)=12,AVERAGE(Q_mensual!I62:I73),"") | H7: =IF(COUNT(Q_mensual!J62:J73)=12,AVERAGE(Q_mensual!J62:J73),"") | I7: =IF(COUNT(Q_mensual!K62:K73)=12,AVERAGE(Q_mensual!K62:K73),"") | ... K7: =IF(COUNT(Q_mensual!M62:M73)=12,AVERAGE(Q_mensual!M62:M73),"")
A8: 1987 | B8: =IF(COUNT(Q_mensual!D74:D85)=12,AVERAGE(Q_mensual!D74:D85),"") | C8: =IF(COUNT(Q_mensual!E74:E85)=12,AVERAGE(Q_mensual!E74:E85),"") | D8: =IF(COUNT(Q_mensual!F74:F85)=12,AVERAGE(Q_mensual!F74:F85),"") | E8: =IF(COUNT(Q_mensual!G74:G85)=12,AVERAGE(Q_mensual!G74:G85),"") | F8: =IF(COUNT(Q_mensual!H74:H85)=12,AVERAGE(Q_mensual!H74:H85),"") | G8: =IF(COUNT(Q_mensual!I74:I85)=12,AVERAGE(Q_mensual!I74:I85),"") | H8: =IF(COUNT(Q_mensual!J74:J85)=12,AVERAGE(Q_mensual!J74:J85),"") | I8: =IF(COUNT(Q_mensual!K74:K85)=12,AVERAGE(Q_mensual!K74:K85),"") | ... K8: =IF(COUNT(Q_mensual!M74:M85)=12,AVERAGE(Q_mensual!M74:M85),"")
A9: 1988 | B9: =IF(COUNT(Q_mensual!D86:D97)=12,AVERAGE(Q_mensual!D86:D97),"") | C9: =IF(COUNT(Q_mensual!E86:E97)=12,AVERAGE(Q_mensual!E86:E97),"") | D9: =IF(COUNT(Q_mensual!F86:F97)=12,AVERAGE(Q_mensual!F86:F97),"") | E9: =IF(COUNT(Q_mensual!G86:G97)=12,AVERAGE(Q_mensual!G86:G97),"") | F9: =IF(COUNT(Q_mensual!H86:H97)=12,AVERAGE(Q_mensual!H86:H97),"") | G9: =IF(COUNT(Q_mensual!I86:I97)=12,AVERAGE(Q_mensual!I86:I97),"") | H9: =IF(COUNT(Q_mensual!J86:J97)=12,AVERAGE(Q_mensual!J86:J97),"") | I9: =IF(COUNT(Q_mensual!K86:K97)=12,AVERAGE(Q_mensual!K86:K97),"") | ... K9: =IF(COUNT(Q_mensual!M86:M97)=12,AVERAGE(Q_mensual!M86:M97),"")
A10: 1989 | B10: =IF(COUNT(Q_mensual!D98:D109)=12,AVERAGE(Q_mensual!D98:D109),"") | C10: =IF(COUNT(Q_mensual!E98:E109)=12,AVERAGE(Q_mensual!E98:E109),"") | D10: =IF(COUNT(Q_mensual!F98:F109)=12,AVERAGE(Q_mensual!F98:F109),"") | E10: =IF(COUNT(Q_mensual!G98:G109)=12,AVERAGE(Q_mensual!G98:G109),"") | F10: =IF(COUNT(Q_mensual!H98:H109)=12,AVERAGE(Q_mensual!H98:H109),"") | G10: =IF(COUNT(Q_mensual!I98:I109)=12,AVERAGE(Q_mensual!I98:I109),"") | H10: =IF(COUNT(Q_mensual!J98:J109)=12,AVERAGE(Q_mensual!J98:J109),"") | I10: =IF(COUNT(Q_mensual!K98:K109)=12,AVERAGE(Q_mensual!K98:K109),"") | ... K10: =IF(COUNT(Q_mensual!M98:M109)=12,AVERAGE(Q_mensual!M98:M109),"")
A11: 1990 | B11: =IF(COUNT(Q_mensual!D110:D121)=12,AVERAGE(Q_mensual!D110:D121),"") | C11: =IF(COUNT(Q_mensual!E110:E121)=12,AVERAGE(Q_mensual!E110:E121),"") | D11: =IF(COUNT(Q_mensual!F110:F121)=12,AVERAGE(Q_mensual!F110:F121),"") | E11: =IF(COUNT(Q_mensual!G110:G121)=12,AVERAGE(Q_mensual!G110:G121),"") | F11: =IF(COUNT(Q_mensual!H110:H121)=12,AVERAGE(Q_mensual!H110:H121),"") | G11: =IF(COUNT(Q_mensual!I110:I121)=12,AVERAGE(Q_mensual!I110:I121),"") | H11: =IF(COUNT(Q_mensual!J110:J121)=12,AVERAGE(Q_mensual!J110:J121),"") | I11: =IF(COUNT(Q_mensual!K110:K121)=12,AVERAGE(Q_mensual!K110:K121),"") | ... K11: =IF(COUNT(Q_mensual!M110:M121)=12,AVERAGE(Q_mensual!M110:M121),"")
A12: 1991 | B12: =IF(COUNT(Q_mensual!D122:D133)=12,AVERAGE(Q_mensual!D122:D133),"") | C12: =IF(COUNT(Q_mensual!E122:E133)=12,AVERAGE(Q_mensual!E122:E133),"") | D12: =IF(COUNT(Q_mensual!F122:F133)=12,AVERAGE(Q_mensual!F122:F133),"") | E12: =IF(COUNT(Q_mensual!G122:G133)=12,AVERAGE(Q_mensual!G122:G133),"") | F12: =IF(COUNT(Q_mensual!H122:H133)=12,AVERAGE(Q_mensual!H122:H133),"") | G12: =IF(COUNT(Q_mensual!I122:I133)=12,AVERAGE(Q_mensual!I122:I133),"") | H12: =IF(COUNT(Q_mensual!J122:J133)=12,AVERAGE(Q_mensual!J122:J133),"") | I12: =IF(COUNT(Q_mensual!K122:K133)=12,AVERAGE(Q_mensual!K122:K133),"") | ... K12: =IF(COUNT(Q_mensual!M122:M133)=12,AVERAGE(Q_mensual!M122:M133),"")
A13: 1992 | B13: =IF(COUNT(Q_mensual!D134:D145)=12,AVERAGE(Q_mensual!D134:D145),"") | C13: =IF(COUNT(Q_mensual!E134:E145)=12,AVERAGE(Q_mensual!E134:E145),"") | D13: =IF(COUNT(Q_mensual!F134:F145)=12,AVERAGE(Q_mensual!F134:F145),"") | E13: =IF(COUNT(Q_mensual!G134:G145)=12,AVERAGE(Q_mensual!G134:G145),"") | F13: =IF(COUNT(Q_mensual!H134:H145)=12,AVERAGE(Q_mensual!H134:H145),"") | G13: =IF(COUNT(Q_mensual!I134:I145)=12,AVERAGE(Q_mensual!I134:I145),"") | H13: =IF(COUNT(Q_mensual!J134:J145)=12,AVERAGE(Q_mensual!J134:J145),"") | I13: =IF(COUNT(Q_mensual!K134:K145)=12,AVERAGE(Q_mensual!K134:K145),"") | ... K13: =IF(COUNT(Q_mensual!M134:M145)=12,AVERAGE(Q_mensual!M134:M145),"")
A14: 1993 | B14: =IF(COUNT(Q_mensual!D146:D157)=12,AVERAGE(Q_mensual!D146:D157),"") | C14: =IF(COUNT(Q_mensual!E146:E157)=12,AVERAGE(Q_mensual!E146:E157),"") | D14: =IF(COUNT(Q_mensual!F146:F157)=12,AVERAGE(Q_mensual!F146:F157),"") | E14: =IF(COUNT(Q_mensual!G146:G157)=12,AVERAGE(Q_mensual!G146:G157),"") | F14: =IF(COUNT(Q_mensual!H146:H157)=12,AVERAGE(Q_mensual!H146:H157),"") | G14: =IF(COUNT(Q_mensual!I146:I157)=12,AVERAGE(Q_mensual!I146:I157),"") | H14: =IF(COUNT(Q_mensual!J146:J157)=12,AVERAGE(Q_mensual!J146:J157),"") | I14: =IF(COUNT(Q_mensual!K146:K157)=12,AVERAGE(Q_mensual!K146:K157),"") | ... K14: =IF(COUNT(Q_mensual!M146:M157)=12,AVERAGE(Q_mensual!M146:M157),"")
A15: 1994 | B15: =IF(COUNT(Q_mensual!D158:D169)=12,AVERAGE(Q_mensual!D158:D169),"") | C15: =IF(COUNT(Q_mensual!E158:E169)=12,AVERAGE(Q_mensual!E158:E169),"") | D15: =IF(COUNT(Q_mensual!F158:F169)=12,AVERAGE(Q_mensual!F158:F169),"") | E15: =IF(COUNT(Q_mensual!G158:G169)=12,AVERAGE(Q_mensual!G158:G169),"") | F15: =IF(COUNT(Q_mensual!H158:H169)=12,AVERAGE(Q_mensual!H158:H169),"") | G15: =IF(COUNT(Q_mensual!I158:I169)=12,AVERAGE(Q_mensual!I158:I169),"") | H15: =IF(COUNT(Q_mensual!J158:J169)=12,AVERAGE(Q_mensual!J158:J169),"") | I15: =IF(COUNT(Q_mensual!K158:K169)=12,AVERAGE(Q_mensual!K158:K169),"") | ... K15: =IF(COUNT(Q_mensual!M158:M169)=12,AVERAGE(Q_mensual!M158:M169),"")
A16: 1995 | B16: =IF(COUNT(Q_mensual!D170:D181)=12,AVERAGE(Q_mensual!D170:D181),"") | C16: =IF(COUNT(Q_mensual!E170:E181)=12,AVERAGE(Q_mensual!E170:E181),"") | D16: =IF(COUNT(Q_mensual!F170:F181)=12,AVERAGE(Q_mensual!F170:F181),"") | E16: =IF(COUNT(Q_mensual!G170:G181)=12,AVERAGE(Q_mensual!G170:G181),"") | F16: =IF(COUNT(Q_mensual!H170:H181)=12,AVERAGE(Q_mensual!H170:H181),"") | G16: =IF(COUNT(Q_mensual!I170:I181)=12,AVERAGE(Q_mensual!I170:I181),"") | H16: =IF(COUNT(Q_mensual!J170:J181)=12,AVERAGE(Q_mensual!J170:J181),"") | I16: =IF(COUNT(Q_mensual!K170:K181)=12,AVERAGE(Q_mensual!K170:K181),"") | ... K16: =IF(COUNT(Q_mensual!M170:M181)=12,AVERAGE(Q_mensual!M170:M181),"")
A17: 1996 | B17: =IF(COUNT(Q_mensual!D182:D193)=12,AVERAGE(Q_mensual!D182:D193),"") | C17: =IF(COUNT(Q_mensual!E182:E193)=12,AVERAGE(Q_mensual!E182:E193),"") | D17: =IF(COUNT(Q_mensual!F182:F193)=12,AVERAGE(Q_mensual!F182:F193),"") | E17: =IF(COUNT(Q_mensual!G182:G193)=12,AVERAGE(Q_mensual!G182:G193),"") | F17: =IF(COUNT(Q_mensual!H182:H193)=12,AVERAGE(Q_mensual!H182:H193),"") | G17: =IF(COUNT(Q_mensual!I182:I193)=12,AVERAGE(Q_mensual!I182:I193),"") | H17: =IF(COUNT(Q_mensual!J182:J193)=12,AVERAGE(Q_mensual!J182:J193),"") | I17: =IF(COUNT(Q_mensual!K182:K193)=12,AVERAGE(Q_mensual!K182:K193),"") | ... K17: =IF(COUNT(Q_mensual!M182:M193)=12,AVERAGE(Q_mensual!M182:M193),"")
A18: 1997 | B18: =IF(COUNT(Q_mensual!D194:D205)=12,AVERAGE(Q_mensual!D194:D205),"") | C18: =IF(COUNT(Q_mensual!E194:E205)=12,AVERAGE(Q_mensual!E194:E205),"") | D18: =IF(COUNT(Q_mensual!F194:F205)=12,AVERAGE(Q_mensual!F194:F205),"") | E18: =IF(COUNT(Q_mensual!G194:G205)=12,AVERAGE(Q_mensual!G194:G205),"") | F18: =IF(COUNT(Q_mensual!H194:H205)=12,AVERAGE(Q_mensual!H194:H205),"") | G18: =IF(COUNT(Q_mensual!I194:I205)=12,AVERAGE(Q_mensual!I194:I205),"") | H18: =IF(COUNT(Q_mensual!J194:J205)=12,AVERAGE(Q_mensual!J194:J205),"") | I18: =IF(COUNT(Q_mensual!K194:K205)=12,AVERAGE(Q_mensual!K194:K205),"") | ... K18: =IF(COUNT(Q_mensual!M194:M205)=12,AVERAGE(Q_mensual!M194:M205),"")
A19: 1998 | B19: =IF(COUNT(Q_mensual!D206:D217)=12,AVERAGE(Q_mensual!D206:D217),"") | C19: =IF(COUNT(Q_mensual!E206:E217)=12,AVERAGE(Q_mensual!E206:E217),"") | D19: =IF(COUNT(Q_mensual!F206:F217)=12,AVERAGE(Q_mensual!F206:F217),"") | E19: =IF(COUNT(Q_mensual!G206:G217)=12,AVERAGE(Q_mensual!G206:G217),"") | F19: =IF(COUNT(Q_mensual!H206:H217)=12,AVERAGE(Q_mensual!H206:H217),"") | G19: =IF(COUNT(Q_mensual!I206:I217)=12,AVERAGE(Q_mensual!I206:I217),"") | H19: =IF(COUNT(Q_mensual!J206:J217)=12,AVERAGE(Q_mensual!J206:J217),"") | I19: =IF(COUNT(Q_mensual!K206:K217)=12,AVERAGE(Q_mensual!K206:K217),"") | ... K19: =IF(COUNT(Q_mensual!M206:M217)=12,AVERAGE(Q_mensual!M206:M217),"")
A20: 1999 | B20: =IF(COUNT(Q_mensual!D218:D229)=12,AVERAGE(Q_mensual!D218:D229),"") | C20: =IF(COUNT(Q_mensual!E218:E229)=12,AVERAGE(Q_mensual!E218:E229),"") | D20: =IF(COUNT(Q_mensual!F218:F229)=12,AVERAGE(Q_mensual!F218:F229),"") | E20: =IF(COUNT(Q_mensual!G218:G229)=12,AVERAGE(Q_mensual!G218:G229),"") | F20: =IF(COUNT(Q_mensual!H218:H229)=12,AVERAGE(Q_mensual!H218:H229),"") | G20: =IF(COUNT(Q_mensual!I218:I229)=12,AVERAGE(Q_mensual!I218:I229),"") | H20: =IF(COUNT(Q_mensual!J218:J229)=12,AVERAGE(Q_mensual!J218:J229),"") | I20: =IF(COUNT(Q_mensual!K218:K229)=12,AVERAGE(Q_mensual!K218:K229),"") | ... K20: =IF(COUNT(Q_mensual!M218:M229)=12,AVERAGE(Q_mensual!M218:M229),"")
A21: 2000 | B21: =IF(COUNT(Q_mensual!D230:D241)=12,AVERAGE(Q_mensual!D230:D241),"") | C21: =IF(COUNT(Q_mensual!E230:E241)=12,AVERAGE(Q_mensual!E230:E241),"") | D21: =IF(COUNT(Q_mensual!F230:F241)=12,AVERAGE(Q_mensual!F230:F241),"") | E21: =IF(COUNT(Q_mensual!G230:G241)=12,AVERAGE(Q_mensual!G230:G241),"") | F21: =IF(COUNT(Q_mensual!H230:H241)=12,AVERAGE(Q_mensual!H230:H241),"") | G21: =IF(COUNT(Q_mensual!I230:I241)=12,AVERAGE(Q_mensual!I230:I241),"") | H21: =IF(COUNT(Q_mensual!J230:J241)=12,AVERAGE(Q_mensual!J230:J241),"") | I21: =IF(COUNT(Q_mensual!K230:K241)=12,AVERAGE(Q_mensual!K230:K241),"") | ... K21: =IF(COUNT(Q_mensual!M230:M241)=12,AVERAGE(Q_mensual!M230:M241),"")
A22: 2001 | B22: =IF(COUNT(Q_mensual!D242:D253)=12,AVERAGE(Q_mensual!D242:D253),"") | C22: =IF(COUNT(Q_mensual!E242:E253)=12,AVERAGE(Q_mensual!E242:E253),"") | D22: =IF(COUNT(Q_mensual!F242:F253)=12,AVERAGE(Q_mensual!F242:F253),"") | E22: =IF(COUNT(Q_mensual!G242:G253)=12,AVERAGE(Q_mensual!G242:G253),"") | F22: =IF(COUNT(Q_mensual!H242:H253)=12,AVERAGE(Q_mensual!H242:H253),"") | G22: =IF(COUNT(Q_mensual!I242:I253)=12,AVERAGE(Q_mensual!I242:I253),"") | H22: =IF(COUNT(Q_mensual!J242:J253)=12,AVERAGE(Q_mensual!J242:J253),"") | I22: =IF(COUNT(Q_mensual!K242:K253)=12,AVERAGE(Q_mensual!K242:K253),"") | ... K22: =IF(COUNT(Q_mensual!M242:M253)=12,AVERAGE(Q_mensual!M242:M253),"")
A23: 2002 | B23: =IF(COUNT(Q_mensual!D254:D265)=12,AVERAGE(Q_mensual!D254:D265),"") | C23: =IF(COUNT(Q_mensual!E254:E265)=12,AVERAGE(Q_mensual!E254:E265),"") | D23: =IF(COUNT(Q_mensual!F254:F265)=12,AVERAGE(Q_mensual!F254:F265),"") | E23: =IF(COUNT(Q_mensual!G254:G265)=12,AVERAGE(Q_mensual!G254:G265),"") | F23: =IF(COUNT(Q_mensual!H254:H265)=12,AVERAGE(Q_mensual!H254:H265),"") | G23: =IF(COUNT(Q_mensual!I254:I265)=12,AVERAGE(Q_mensual!I254:I265),"") | H23: =IF(COUNT(Q_mensual!J254:J265)=12,AVERAGE(Q_mensual!J254:J265),"") | I23: =IF(COUNT(Q_mensual!K254:K265)=12,AVERAGE(Q_mensual!K254:K265),"") | ... K23: =IF(COUNT(Q_mensual!M254:M265)=12,AVERAGE(Q_mensual!M254:M265),"")
A24: 2003 | B24: =IF(COUNT(Q_mensual!D266:D277)=12,AVERAGE(Q_mensual!D266:D277),"") | C24: =IF(COUNT(Q_mensual!E266:E277)=12,AVERAGE(Q_mensual!E266:E277),"") | D24: =IF(COUNT(Q_mensual!F266:F277)=12,AVERAGE(Q_mensual!F266:F277),"") | E24: =IF(COUNT(Q_mensual!G266:G277)=12,AVERAGE(Q_mensual!G266:G277),"") | F24: =IF(COUNT(Q_mensual!H266:H277)=12,AVERAGE(Q_mensual!H266:H277),"") | G24: =IF(COUNT(Q_mensual!I266:I277)=12,AVERAGE(Q_mensual!I266:I277),"") | H24: =IF(COUNT(Q_mensual!J266:J277)=12,AVERAGE(Q_mensual!J266:J277),"") | I24: =IF(COUNT(Q_mensual!K266:K277)=12,AVERAGE(Q_mensual!K266:K277),"") | ... K24: =IF(COUNT(Q_mensual!M266:M277)=12,AVERAGE(Q_mensual!M266:M277),"")
A25: 2004 | B25: =IF(COUNT(Q_mensual!D278:D289)=12,AVERAGE(Q_mensual!D278:D289),"") | C25: =IF(COUNT(Q_mensual!E278:E289)=12,AVERAGE(Q_mensual!E278:E289),"") | D25: =IF(COUNT(Q_mensual!F278:F289)=12,AVERAGE(Q_mensual!F278:F289),"") | E25: =IF(COUNT(Q_mensual!G278:G289)=12,AVERAGE(Q_mensual!G278:G289),"") | F25: =IF(COUNT(Q_mensual!H278:H289)=12,AVERAGE(Q_mensual!H278:H289),"") | G25: =IF(COUNT(Q_mensual!I278:I289)=12,AVERAGE(Q_mensual!I278:I289),"") | H25: =IF(COUNT(Q_mensual!J278:J289)=12,AVERAGE(Q_mensual!J278:J289),"") | I25: =IF(COUNT(Q_mensual!K278:K289)=12,AVERAGE(Q_mensual!K278:K289),"") | ... K25: =IF(COUNT(Q_mensual!M278:M289)=12,AVERAGE(Q_mensual!M278:M289),"")
A26: 2005 | B26: =IF(COUNT(Q_mensual!D290:D301)=12,AVERAGE(Q_mensual!D290:D301),"") | C26: =IF(COUNT(Q_mensual!E290:E301)=12,AVERAGE(Q_mensual!E290:E301),"") | D26: =IF(COUNT(Q_mensual!F290:F301)=12,AVERAGE(Q_mensual!F290:F301),"") | E26: =IF(COUNT(Q_mensual!G290:G301)=12,AVERAGE(Q_mensual!G290:G301),"") | F26: =IF(COUNT(Q_mensual!H290:H301)=12,AVERAGE(Q_mensual!H290:H301),"") | G26: =IF(COUNT(Q_mensual!I290:I301)=12,AVERAGE(Q_mensual!I290:I301),"") | H26: =IF(COUNT(Q_mensual!J290:J301)=12,AVERAGE(Q_mensual!J290:J301),"") | I26: =IF(COUNT(Q_mensual!K290:K301)=12,AVERAGE(Q_mensual!K290:K301),"") | ... K26: =IF(COUNT(Q_mensual!M290:M301)=12,AVERAGE(Q_mensual!M290:M301),"")
A27: 2006 | B27: =IF(COUNT(Q_mensual!D302:D313)=12,AVERAGE(Q_mensual!D302:D313),"") | C27: =IF(COUNT(Q_mensual!E302:E313)=12,AVERAGE(Q_mensual!E302:E313),"") | D27: =IF(COUNT(Q_mensual!F302:F313)=12,AVERAGE(Q_mensual!F302:F313),"") | E27: =IF(COUNT(Q_mensual!G302:G313)=12,AVERAGE(Q_mensual!G302:G313),"") | F27: =IF(COUNT(Q_mensual!H302:H313)=12,AVERAGE(Q_mensual!H302:H313),"") | G27: =IF(COUNT(Q_mensual!I302:I313)=12,AVERAGE(Q_mensual!I302:I313),"") | H27: =IF(COUNT(Q_mensual!J302:J313)=12,AVERAGE(Q_mensual!J302:J313),"") | I27: =IF(COUNT(Q_mensual!K302:K313)=12,AVERAGE(Q_mensual!K302:K313),"") | ... K27: =IF(COUNT(Q_mensual!M302:M313)=12,AVERAGE(Q_mensual!M302:M313),"")
A28: 2007 | B28: =IF(COUNT(Q_mensual!D314:D325)=12,AVERAGE(Q_mensual!D314:D325),"") | C28: =IF(COUNT(Q_mensual!E314:E325)=12,AVERAGE(Q_mensual!E314:E325),"") | D28: =IF(COUNT(Q_mensual!F314:F325)=12,AVERAGE(Q_mensual!F314:F325),"") | E28: =IF(COUNT(Q_mensual!G314:G325)=12,AVERAGE(Q_mensual!G314:G325),"") | F28: =IF(COUNT(Q_mensual!H314:H325)=12,AVERAGE(Q_mensual!H314:H325),"") | G28: =IF(COUNT(Q_mensual!I314:I325)=12,AVERAGE(Q_mensual!I314:I325),"") | H28: =IF(COUNT(Q_mensual!J314:J325)=12,AVERAGE(Q_mensual!J314:J325),"") | I28: =IF(COUNT(Q_mensual!K314:K325)=12,AVERAGE(Q_mensual!K314:K325),"") | ... K28: =IF(COUNT(Q_mensual!M314:M325)=12,AVERAGE(Q_mensual!M314:M325),"")
A29: 2008 | B29: =IF(COUNT(Q_mensual!D326:D337)=12,AVERAGE(Q_mensual!D326:D337),"") | C29: =IF(COUNT(Q_mensual!E326:E337)=12,AVERAGE(Q_mensual!E326:E337),"") | D29: =IF(COUNT(Q_mensual!F326:F337)=12,AVERAGE(Q_mensual!F326:F337),"") | E29: =IF(COUNT(Q_mensual!G326:G337)=12,AVERAGE(Q_mensual!G326:G337),"") | F29: =IF(COUNT(Q_mensual!H326:H337)=12,AVERAGE(Q_mensual!H326:H337),"") | G29: =IF(COUNT(Q_mensual!I326:I337)=12,AVERAGE(Q_mensual!I326:I337),"") | H29: =IF(COUNT(Q_mensual!J326:J337)=12,AVERAGE(Q_mensual!J326:J337),"") | I29: =IF(COUNT(Q_mensual!K326:K337)=12,AVERAGE(Q_mensual!K326:K337),"") | ... K29: =IF(COUNT(Q_mensual!M326:M337)=12,AVERAGE(Q_mensual!M326:M337),"")
A30: 2009 | B30: =IF(COUNT(Q_mensual!D338:D349)=12,AVERAGE(Q_mensual!D338:D349),"") | C30: =IF(COUNT(Q_mensual!E338:E349)=12,AVERAGE(Q_mensual!E338:E349),"") | D30: =IF(COUNT(Q_mensual!F338:F349)=12,AVERAGE(Q_mensual!F338:F349),"") | E30: =IF(COUNT(Q_mensual!G338:G349)=12,AVERAGE(Q_mensual!G338:G349),"") | F30: =IF(COUNT(Q_mensual!H338:H349)=12,AVERAGE(Q_mensual!H338:H349),"") | G30: =IF(COUNT(Q_mensual!I338:I349)=12,AVERAGE(Q_mensual!I338:I349),"") | H30: =IF(COUNT(Q_mensual!J338:J349)=12,AVERAGE(Q_mensual!J338:J349),"") | I30: =IF(COUNT(Q_mensual!K338:K349)=12,AVERAGE(Q_mensual!K338:K349),"") | ... K30: =IF(COUNT(Q_mensual!M338:M349)=12,AVERAGE(Q_mensual!M338:M349),"")
A31: 2010 | B31: =IF(COUNT(Q_mensual!D350:D361)=12,AVERAGE(Q_mensual!D350:D361),"") | C31: =IF(COUNT(Q_mensual!E350:E361)=12,AVERAGE(Q_mensual!E350:E361),"") | D31: =IF(COUNT(Q_mensual!F350:F361)=12,AVERAGE(Q_mensual!F350:F361),"") | E31: =IF(COUNT(Q_mensual!G350:G361)=12,AVERAGE(Q_mensual!G350:G361),"") | F31: =IF(COUNT(Q_mensual!H350:H361)=12,AVERAGE(Q_mensual!H350:H361),"") | G31: =IF(COUNT(Q_mensual!I350:I361)=12,AVERAGE(Q_mensual!I350:I361),"") | H31: =IF(COUNT(Q_mensual!J350:J361)=12,AVERAGE(Q_mensual!J350:J361),"") | I31: =IF(COUNT(Q_mensual!K350:K361)=12,AVERAGE(Q_mensual!K350:K361),"") | ... K31: =IF(COUNT(Q_mensual!M350:M361)=12,AVERAGE(Q_mensual!M350:M361),"")

Sheet Resumen_Q
A1: Código | B1: Estación | C1: Área (km²) | D1: Años válidos 1981–2010 | E1: Q medio anual multianual (m³/s) | F1: Desv. estándar Q anual (m³/s) | G1: Coef. de variación (%) | H1: Q anual mínimo (m³/s) | I1: Q anual máximo (m³/s) | J1: Rendimiento q (L/s/km²) | K1: Lámina de escorrentía R (mm/año) | L1: Q medio registro completo (m³/s)
A2: 26027010 | B2: La Balsa | C2: =Estaciones!N2 | D2: =COUNT(Q_anual!B2:B31) | E2: =AVERAGE(Q_anual!B2:B31) | F2: =STDEV(Q_anual!B2:B31) | G2: =F2/E2*100 | H2: =MIN(Q_anual!B2:B31) | I2: =MAX(Q_anual!B2:B31) | J2: =E2/C2*1000 | K2: =E2*31557600/(C2*1000000)*1000 | L2: 189.4
A3: 26067010 | B3: Juanchito | C3: =Estaciones!N3 | D3: =COUNT(Q_anual!C2:C31) | E3: =AVERAGE(Q_anual!C2:C31) | F3: =STDEV(Q_anual!C2:C31) | G3: =F3/E3*100 | H3: =MIN(Q_anual!C2:C31) | I3: =MAX(Q_anual!C2:C31) | J3: =E3/C3*1000 | K3: =E3*31557600/(C3*1000000)*1000 | L3: 298.2
A4: 26107070 | B4: La Victoria | C4: =Estaciones!N4 | D4: =COUNT(Q_anual!D2:D31) | E4: =AVERAGE(Q_anual!D2:D31) | F4: =STDEV(Q_anual!D2:D31) | G4: =F4/E4*100 | H4: =MIN(Q_anual!D2:D31) | I4: =MAX(Q_anual!D2:D31) | J4: =E4/C4*1000 | K4: =E4*31557600/(C4*1000000)*1000 | L4: 379.5
A5: 26177030 | B5: La Virginia | C5: =Estaciones!N5 | D5: =COUNT(Q_anual!E2:E31) | E5: =AVERAGE(Q_anual!E2:E31) | F5: =STDEV(Q_anual!E2:E31) | G5: =F5/E5*100 | H5: =MIN(Q_anual!E2:E31) | I5: =MAX(Q_anual!E2:E31) | J5: =E5/C5*1000 | K5: =E5*31557600/(C5*1000000)*1000 | L5: 547.9
A6: 26167070 | B6: Irra | C6: =Estaciones!N6 | D6: =COUNT(Q_anual!F2:F31) | E6: =AVERAGE(Q_anual!F2:F31) | F6: =STDEV(Q_anual!F2:F31) | G6: =F6/E6*100 | H6: =MIN(Q_anual!F2:F31) | I6: =MAX(Q_anual!F2:F31) | J6: =E6/C6*1000 | K6: =E6*31557600/(C6*1000000)*1000 | L6: 674.3
A7: 26187110 | B7: La Pintada | C7: =Estaciones!N7 | D7: =COUNT(Q_anual!G2:G31) | E7: =AVERAGE(Q_anual!G2:G31) | F7: =STDEV(Q_anual!G2:G31) | G7: =F7/E7*100 | H7: =MIN(Q_anual!G2:G31) | I7: =MAX(Q_anual!G2:G31) | J7: =E7/C7*1000 | K7: =E7*31557600/(C7*1000000)*1000 | L7: 716.7
A8: 26207030 | B8: Puente Iglesias | C8: =Estaciones!N8 | D8: =COUNT(Q_anual!H2:H31) | E8: =AVERAGE(Q_anual!H2:H31) | F8: =STDEV(Q_anual!H2:H31) | G8: =F8/E8*100 | H8: =MIN(Q_anual!H2:H31) | I8: =MAX(Q_anual!H2:H31) | J8: =E8/C8*1000 | K8: =E8*31557600/(C8*1000000)*1000 | L8: 760.3
A9: 26207080 | B9: Bolombolo | C9: =Estaciones!N9 | D9: =COUNT(Q_anual!I2:I31) | E9: =AVERAGE(Q_anual!I2:I31) | F9: =STDEV(Q_anual!I2:I31) | G9: =F9/E9*100 | H9: =MIN(Q_anual!I2:I31) | I9: =MAX(Q_anual!I2:I31) | J9: =E9/C9*1000 | K9: =E9*31557600/(C9*1000000)*1000 | L9: 865.3
A10: 26217050 | B10: Cañafisto | C10: =Estaciones!N10 | D10: =COUNT(Q_anual!J2:J31) | E10: =AVERAGE(Q_anual!J2:J31) | F10: =STDEV(Q_anual!J2:J31) | G10: =F10/E10*100 | H10: =MIN(Q_anual!J2:J31) | I10: =MAX(Q_anual!J2:J31) | J10: =E10/C10*1000 | K10: =E10*31557600/(C10*1000000)*1000 | L10: 905.4
A11: 26237040 | B11: Puerto Valdivia | C11: =Estaciones!N11 | D11: =COUNT(Q_anual!K2:K31) | E11: =AVERAGE(Q_anual!K2:K31) | F11: =STDEV(Q_anual!K2:K31) | G11: =F11/E11*100 | H11: =MIN(Q_anual!K2:K31) | I11: =MAX(Q_anual!K2:K31) | J11: =E11/C11*1000 | K11: =E11*31557600/(C11*1000000)*1000 | L11: 1120.2
A13: Transferencia al punto de cierre (presa Hidroituango) por relación de áreas
A14: Área cuenca hasta Hidroituango (km²) | B14: 35991.775
A15: Área Pto. Valdivia (km²) | B15: =C11
A16: Q medio Pto. Valdivia (m³/s) | B16: =E11
A17: Q medio estimado en Hidroituango (m³/s) | B17: =B16*B14/B15
A18: Lámina de escorrentía en Hidroituango (mm/año) | B18: =B17*31557600/(B14*1000000)*1000

Sheet Ciclo_anual
A1: Mes | B1: N.º mes | C1: La Balsa | D1: Juanchito | E1: La Victoria | F1: La Virginia | G1: Irra | H1: La Pintada | I1: Puente Iglesias | J1: Bolombolo | K1: Cañafisto | L1: Puerto Valdivia
A2: Ene | B2: 1 | C2: =AVERAGEIFS(Q_mensual!D2:D361,Q_mensual!$C$2:$C$361,B2) | D2: =AVERAGEIFS(Q_mensual!E2:E361,Q_mensual!$C$2:$C$361,B2) | E2: =AVERAGEIFS(Q_mensual!F2:F361,Q_mensual!$C$2:$C$361,B2) | F2: =AVERAGEIFS(Q_mensual!G2:G361,Q_mensual!$C$2:$C$361,B2) | G2: =AVERAGEIFS(Q_mensual!H2:H361,Q_mensual!$C$2:$C$361,B2) | H2: =AVERAGEIFS(Q_mensual!I2:I361,Q_mensual!$C$2:$C$361,B2) | I2: =AVERAGEIFS(Q_mensual!J2:J361,Q_mensual!$C$2:$C$361,B2) | J2: =AVERAGEIFS(Q_mensual!K2:K361,Q_mensual!$C$2:$C$361,B2) | K2: =AVERAGEIFS(Q_mensual!L2:L361,Q_mensual!$C$2:$C$361,B2) | L2: =AVERAGEIFS(Q_mensual!M2:M361,Q_mensual!$C$2:$C$361,B2)
A3: Feb | B3: 2 | C3: =AVERAGEIFS(Q_mensual!D2:D361,Q_mensual!$C$2:$C$361,B3) | D3: =AVERAGEIFS(Q_mensual!E2:E361,Q_mensual!$C$2:$C$361,B3) | E3: =AVERAGEIFS(Q_mensual!F2:F361,Q_mensual!$C$2:$C$361,B3) | F3: =AVERAGEIFS(Q_mensual!G2:G361,Q_mensual!$C$2:$C$361,B3) | G3: =AVERAGEIFS(Q_mensual!H2:H361,Q_mensual!$C$2:$C$361,B3) | H3: =AVERAGEIFS(Q_mensual!I2:I361,Q_mensual!$C$2:$C$361,B3) | I3: =AVERAGEIFS(Q_mensual!J2:J361,Q_mensual!$C$2:$C$361,B3) | J3: =AVERAGEIFS(Q_mensual!K2:K361,Q_mensual!$C$2:$C$361,B3) | K3: =AVERAGEIFS(Q_mensual!L2:L361,Q_mensual!$C$2:$C$361,B3) | L3: =AVERAGEIFS(Q_mensual!M2:M361,Q_mensual!$C$2:$C$361,B3)
A4: Mar | B4: 3 | C4: =AVERAGEIFS(Q_mensual!D2:D361,Q_mensual!$C$2:$C$361,B4) | D4: =AVERAGEIFS(Q_mensual!E2:E361,Q_mensual!$C$2:$C$361,B4) | E4: =AVERAGEIFS(Q_mensual!F2:F361,Q_mensual!$C$2:$C$361,B4) | F4: =AVERAGEIFS(Q_mensual!G2:G361,Q_mensual!$C$2:$C$361,B4) | G4: =AVERAGEIFS(Q_mensual!H2:H361,Q_mensual!$C$2:$C$361,B4) | H4: =AVERAGEIFS(Q_mensual!I2:I361,Q_mensual!$C$2:$C$361,B4) | I4: =AVERAGEIFS(Q_mensual!J2:J361,Q_mensual!$C$2:$C$361,B4) | J4: =AVERAGEIFS(Q_mensual!K2:K361,Q_mensual!$C$2:$C$361,B4) | K4: =AVERAGEIFS(Q_mensual!L2:L361,Q_mensual!$C$2:$C$361,B4) | L4: =AVERAGEIFS(Q_mensual!M2:M361,Q_mensual!$C$2:$C$361,B4)
A5: Abr | B5: 4 | C5: =AVERAGEIFS(Q_mensual!D2:D361,Q_mensual!$C$2:$C$361,B5) | D5: =AVERAGEIFS(Q_mensual!E2:E361,Q_mensual!$C$2:$C$361,B5) | E5: =AVERAGEIFS(Q_mensual!F2:F361,Q_mensual!$C$2:$C$361,B5) | F5: =AVERAGEIFS(Q_mensual!G2:G361,Q_mensual!$C$2:$C$361,B5) | G5: =AVERAGEIFS(Q_mensual!H2:H361,Q_mensual!$C$2:$C$361,B5) | H5: =AVERAGEIFS(Q_mensual!I2:I361,Q_mensual!$C$2:$C$361,B5) | I5: =AVERAGEIFS(Q_mensual!J2:J361,Q_mensual!$C$2:$C$361,B5) | J5: =AVERAGEIFS(Q_mensual!K2:K361,Q_mensual!$C$2:$C$361,B5) | K5: =AVERAGEIFS(Q_mensual!L2:L361,Q_mensual!$C$2:$C$361,B5) | L5: =AVERAGEIFS(Q_mensual!M2:M361,Q_mensual!$C$2:$C$361,B5)
A6: May | B6: 5 | C6: =AVERAGEIFS(Q_mensual!D2:D361,Q_mensual!$C$2:$C$361,B6) | D6: =AVERAGEIFS(Q_mensual!E2:E361,Q_mensual!$C$2:$C$361,B6) | E6: =AVERAGEIFS(Q_mensual!F2:F361,Q_mensual!$C$2:$C$361,B6) | F6: =AVERAGEIFS(Q_mensual!G2:G361,Q_mensual!$C$2:$C$361,B6) | G6: =AVERAGEIFS(Q_mensual!H2:H361,Q_mensual!$C$2:$C$361,B6) | H6: =AVERAGEIFS(Q_mensual!I2:I361,Q_mensual!$C$2:$C$361,B6) | I6: =AVERAGEIFS(Q_mensual!J2:J361,Q_mensual!$C$2:$C$361,B6) | J6: =AVERAGEIFS(Q_mensual!K2:K361,Q_mensual!$C$2:$C$361,B6) | K6: =AVERAGEIFS(Q_mensual!L2:L361,Q_mensual!$C$2:$C$361,B6) | L6: =AVERAGEIFS(Q_mensual!M2:M361,Q_mensual!$C$2:$C$361,B6)
A7: Jun | B7: 6 | C7: =AVERAGEIFS(Q_mensual!D2:D361,Q_mensual!$C$2:$C$361,B7) | D7: =AVERAGEIFS(Q_mensual!E2:E361,Q_mensual!$C$2:$C$361,B7) | E7: =AVERAGEIFS(Q_mensual!F2:F361,Q_mensual!$C$2:$C$361,B7) | F7: =AVERAGEIFS(Q_mensual!G2:G361,Q_mensual!$C$2:$C$361,B7) | G7: =AVERAGEIFS(Q_mensual!H2:H361,Q_mensual!$C$2:$C$361,B7) | H7: =AVERAGEIFS(Q_mensual!I2:I361,Q_mensual!$C$2:$C$361,B7) | I7: =AVERAGEIFS(Q_mensual!J2:J361,Q_mensual!$C$2:$C$361,B7) | J7: =AVERAGEIFS(Q_mensual!K2:K361,Q_mensual!$C$2:$C$361,B7) | K7: =AVERAGEIFS(Q_mensual!L2:L361,Q_mensual!$C$2:$C$361,B7) | L7: =AVERAGEIFS(Q_mensual!M2:M361,Q_mensual!$C$2:$C$361,B7)
A8: Jul | B8: 7 | C8: =AVERAGEIFS(Q_mensual!D2:D361,Q_mensual!$C$2:$C$361,B8) | D8: =AVERAGEIFS(Q_mensual!E2:E361,Q_mensual!$C$2:$C$361,B8) | E8: =AVERAGEIFS(Q_mensual!F2:F361,Q_mensual!$C$2:$C$361,B8) | F8: =AVERAGEIFS(Q_mensual!G2:G361,Q_mensual!$C$2:$C$361,B8) | G8: =AVERAGEIFS(Q_mensual!H2:H361,Q_mensual!$C$2:$C$361,B8) | H8: =AVERAGEIFS(Q_mensual!I2:I361,Q_mensual!$C$2:$C$361,B8) | I8: =AVERAGEIFS(Q_mensual!J2:J361,Q_mensual!$C$2:$C$361,B8) | J8: =AVERAGEIFS(Q_mensual!K2:K361,Q_mensual!$C$2:$C$361,B8) | K8: =AVERAGEIFS(Q_mensual!L2:L361,Q_mensual!$C$2:$C$361,B8) | L8: =AVERAGEIFS(Q_mensual!M2:M361,Q_mensual!$C$2:$C$361,B8)
A9: Ago | B9: 8 | C9: =AVERAGEIFS(Q_mensual!D2:D361,Q_mensual!$C$2:$C$361,B9) | D9: =AVERAGEIFS(Q_mensual!E2:E361,Q_mensual!$C$2:$C$361,B9) | E9: =AVERAGEIFS(Q_mensual!F2:F361,Q_mensual!$C$2:$C$361,B9) | F9: =AVERAGEIFS(Q_mensual!G2:G361,Q_mensual!$C$2:$C$361,B9) | G9: =AVERAGEIFS(Q_mensual!H2:H361,Q_mensual!$C$2:$C$361,B9) | H9: =AVERAGEIFS(Q_mensual!I2:I361,Q_mensual!$C$2:$C$361,B9) | I9: =AVERAGEIFS(Q_mensual!J2:J361,Q_mensual!$C$2:$C$361,B9) | J9: =AVERAGEIFS(Q_mensual!K2:K361,Q_mensual!$C$2:$C$361,B9) | K9: =AVERAGEIFS(Q_mensual!L2:L361,Q_mensual!$C$2:$C$361,B9) | L9: =AVERAGEIFS(Q_mensual!M2:M361,Q_mensual!$C$2:$C$361,B9)
A10: Sep | B10: 9 | C10: =AVERAGEIFS(Q_mensual!D2:D361,Q_mensual!$C$2:$C$361,B10) | D10: =AVERAGEIFS(Q_mensual!E2:E361,Q_mensual!$C$2:$C$361,B10) | E10: =AVERAGEIFS(Q_mensual!F2:F361,Q_mensual!$C$2:$C$361,B10) | F10: =AVERAGEIFS(Q_mensual!G2:G361,Q_mensual!$C$2:$C$361,B10) | G10: =AVERAGEIFS(Q_mensual!H2:H361,Q_mensual!$C$2:$C$361,B10) | H10: =AVERAGEIFS(Q_mensual!I2:I361,Q_mensual!$C$2:$C$361,B10) | I10: =AVERAGEIFS(Q_mensual!J2:J361,Q_mensual!$C$2:$C$361,B10) | J10: =AVERAGEIFS(Q_mensual!K2:K361,Q_mensual!$C$2:$C$361,B10) | K10: =AVERAGEIFS(Q_mensual!L2:L361,Q_mensual!$C$2:$C$361,B10) | L10: =AVERAGEIFS(Q_mensual!M2:M361,Q_mensual!$C$2:$C$361,B10)
A11: Oct | B11: 10 | C11: =AVERAGEIFS(Q_mensual!D2:D361,Q_mensual!$C$2:$C$361,B11) | D11: =AVERAGEIFS(Q_mensual!E2:E361,Q_mensual!$C$2:$C$361,B11) | E11: =AVERAGEIFS(Q_mensual!F2:F361,Q_mensual!$C$2:$C$361,B11) | F11: =AVERAGEIFS(Q_mensual!G2:G361,Q_mensual!$C$2:$C$361,B11) | G11: =AVERAGEIFS(Q_mensual!H2:H361,Q_mensual!$C$2:$C$361,B11) | H11: =AVERAGEIFS(Q_mensual!I2:I361,Q_mensual!$C$2:$C$361,B11) | I11: =AVERAGEIFS(Q_mensual!J2:J361,Q_mensual!$C$2:$C$361,B11) | J11: =AVERAGEIFS(Q_mensual!K2:K361,Q_mensual!$C$2:$C$361,B11) | K11: =AVERAGEIFS(Q_mensual!L2:L361,Q_mensual!$C$2:$C$361,B11) | L11: =AVERAGEIFS(Q_mensual!M2:M361,Q_mensual!$C$2:$C$361,B11)
A12: Nov | B12: 11 | C12: =AVERAGEIFS(Q_mensual!D2:D361,Q_mensual!$C$2:$C$361,B12) | D12: =AVERAGEIFS(Q_mensual!E2:E361,Q_mensual!$C$2:$C$361,B12) | E12: =AVERAGEIFS(Q_mensual!F2:F361,Q_mensual!$C$2:$C$361,B12) | F12: =AVERAGEIFS(Q_mensual!G2:G361,Q_mensual!$C$2:$C$361,B12) | G12: =AVERAGEIFS(Q_mensual!H2:H361,Q_mensual!$C$2:$C$361,B12) | H12: =AVERAGEIFS(Q_mensual!I2:I361,Q_mensual!$C$2:$C$361,B12) | I12: =AVERAGEIFS(Q_mensual!J2:J361,Q_mensual!$C$2:$C$361,B12) | J12: =AVERAGEIFS(Q_mensual!K2:K361,Q_mensual!$C$2:$C$361,B12) | K12: =AVERAGEIFS(Q_mensual!L2:L361,Q_mensual!$C$2:$C$361,B12) | L12: =AVERAGEIFS(Q_mensual!M2:M361,Q_mensual!$C$2:$C$361,B12)
A13: Dic | B13: 12 | C13: =AVERAGEIFS(Q_mensual!D2:D361,Q_mensual!$C$2:$C$361,B13) | D13: =AVERAGEIFS(Q_mensual!E2:E361,Q_mensual!$C$2:$C$361,B13) | E13: =AVERAGEIFS(Q_mensual!F2:F361,Q_mensual!$C$2:$C$361,B13) | F13: =AVERAGEIFS(Q_mensual!G2:G361,Q_mensual!$C$2:$C$361,B13) | G13: =AVERAGEIFS(Q_mensual!H2:H361,Q_mensual!$C$2:$C$361,B13) | H13: =AVERAGEIFS(Q_mensual!I2:I361,Q_mensual!$C$2:$C$361,B13) | I13: =AVERAGEIFS(Q_mensual!J2:J361,Q_mensual!$C$2:$C$361,B13) | J13: =AVERAGEIFS(Q_mensual!K2:K361,Q_mensual!$C$2:$C$361,B13) | K13: =AVERAGEIFS(Q_mensual!L2:L361,Q_mensual!$C$2:$C$361,B13) | L13: =AVERAGEIFS(Q_mensual!M2:M361,Q_mensual!$C$2:$C$361,B13)

Sheet Mapa
